[2015-02-22 12:30:00,449] [ERROR] views : index
[2015-02-22 12:30:48,963] [INFO] views : index
[2015-02-22 12:36:54,421] [ERROR] base : Internal Server Error: /admin/app/serverlist/
Traceback (most recent call last):
  File "/data/django_serverauto/env/local/lib/python2.7/site-packages/django/core/handlers/base.py", line 114, in get_response
    response = wrapped_callback(request, *callback_args, **callback_kwargs)
  File "/data/django_serverauto/env/local/lib/python2.7/site-packages/django/contrib/admin/options.py", line 430, in wrapper
    return self.admin_site.admin_view(view)(*args, **kwargs)
  File "/data/django_serverauto/env/local/lib/python2.7/site-packages/django/utils/decorators.py", line 99, in _wrapped_view
    response = view_func(request, *args, **kwargs)
  File "/data/django_serverauto/env/local/lib/python2.7/site-packages/django/views/decorators/cache.py", line 52, in _wrapped_view_func
    response = view_func(request, *args, **kwargs)
  File "/data/django_serverauto/env/local/lib/python2.7/site-packages/django/contrib/admin/sites.py", line 198, in inner
    return view(request, *args, **kwargs)
  File "/data/django_serverauto/env/local/lib/python2.7/site-packages/django/utils/decorators.py", line 29, in _wrapper
    return bound_func(*args, **kwargs)
  File "/data/django_serverauto/env/local/lib/python2.7/site-packages/django/utils/decorators.py", line 99, in _wrapped_view
    response = view_func(request, *args, **kwargs)
  File "/data/django_serverauto/env/local/lib/python2.7/site-packages/django/utils/decorators.py", line 25, in bound_func
    return func(self, *args2, **kwargs2)
  File "/data/django_serverauto/env/local/lib/python2.7/site-packages/django/contrib/admin/options.py", line 1409, in changelist_view
    'selection_note': _('0 of %(cnt)s selected') % {'cnt': len(cl.result_list)},
  File "/data/django_serverauto/env/local/lib/python2.7/site-packages/django/db/models/query.py", line 77, in __len__
    self._fetch_all()
  File "/data/django_serverauto/env/local/lib/python2.7/site-packages/django/db/models/query.py", line 854, in _fetch_all
    self._result_cache = list(self.iterator())
  File "/data/django_serverauto/env/local/lib/python2.7/site-packages/django/db/models/query.py", line 220, in iterator
    for row in compiler.results_iter():
  File "/data/django_serverauto/env/local/lib/python2.7/site-packages/django/db/models/sql/compiler.py", line 710, in results_iter
    for rows in self.execute_sql(MULTI):
  File "/data/django_serverauto/env/local/lib/python2.7/site-packages/django/db/models/sql/compiler.py", line 781, in execute_sql
    cursor.execute(sql, params)
  File "/data/django_serverauto/env/local/lib/python2.7/site-packages/django/db/backends/util.py", line 69, in execute
    return super(CursorDebugWrapper, self).execute(sql, params)
  File "/data/django_serverauto/env/local/lib/python2.7/site-packages/django/db/backends/util.py", line 53, in execute
    return self.cursor.execute(sql, params)
  File "/data/django_serverauto/env/local/lib/python2.7/site-packages/django/db/utils.py", line 99, in __exit__
    six.reraise(dj_exc_type, dj_exc_value, traceback)
  File "/data/django_serverauto/env/local/lib/python2.7/site-packages/django/db/backends/util.py", line 53, in execute
    return self.cursor.execute(sql, params)
  File "/data/django_serverauto/env/local/lib/python2.7/site-packages/django/db/backends/mysql/base.py", line 124, in execute
    return self.cursor.execute(query, args)
  File "/data/django_serverauto/env/local/lib/python2.7/site-packages/MySQLdb/cursors.py", line 205, in execute
    self.errorhandler(self, exc, value)
  File "/data/django_serverauto/env/local/lib/python2.7/site-packages/MySQLdb/connections.py", line 36, in defaulterrorhandler
    raise errorclass, errorvalue
OperationalError: (1054, "Unknown column 'server_list.server_snmp_on' in 'field list'")
[2015-02-22 12:36:54,421] [ERROR] base : Internal Server Error: /admin/app/serverlist/
Traceback (most recent call last):
  File "/data/django_serverauto/env/local/lib/python2.7/site-packages/django/core/handlers/base.py", line 114, in get_response
    response = wrapped_callback(request, *callback_args, **callback_kwargs)
  File "/data/django_serverauto/env/local/lib/python2.7/site-packages/django/contrib/admin/options.py", line 430, in wrapper
    return self.admin_site.admin_view(view)(*args, **kwargs)
  File "/data/django_serverauto/env/local/lib/python2.7/site-packages/django/utils/decorators.py", line 99, in _wrapped_view
    response = view_func(request, *args, **kwargs)
  File "/data/django_serverauto/env/local/lib/python2.7/site-packages/django/views/decorators/cache.py", line 52, in _wrapped_view_func
    response = view_func(request, *args, **kwargs)
  File "/data/django_serverauto/env/local/lib/python2.7/site-packages/django/contrib/admin/sites.py", line 198, in inner
    return view(request, *args, **kwargs)
  File "/data/django_serverauto/env/local/lib/python2.7/site-packages/django/utils/decorators.py", line 29, in _wrapper
    return bound_func(*args, **kwargs)
  File "/data/django_serverauto/env/local/lib/python2.7/site-packages/django/utils/decorators.py", line 99, in _wrapped_view
    response = view_func(request, *args, **kwargs)
  File "/data/django_serverauto/env/local/lib/python2.7/site-packages/django/utils/decorators.py", line 25, in bound_func
    return func(self, *args2, **kwargs2)
  File "/data/django_serverauto/env/local/lib/python2.7/site-packages/django/contrib/admin/options.py", line 1409, in changelist_view
    'selection_note': _('0 of %(cnt)s selected') % {'cnt': len(cl.result_list)},
  File "/data/django_serverauto/env/local/lib/python2.7/site-packages/django/db/models/query.py", line 77, in __len__
    self._fetch_all()
  File "/data/django_serverauto/env/local/lib/python2.7/site-packages/django/db/models/query.py", line 854, in _fetch_all
    self._result_cache = list(self.iterator())
  File "/data/django_serverauto/env/local/lib/python2.7/site-packages/django/db/models/query.py", line 220, in iterator
    for row in compiler.results_iter():
  File "/data/django_serverauto/env/local/lib/python2.7/site-packages/django/db/models/sql/compiler.py", line 710, in results_iter
    for rows in self.execute_sql(MULTI):
  File "/data/django_serverauto/env/local/lib/python2.7/site-packages/django/db/models/sql/compiler.py", line 781, in execute_sql
    cursor.execute(sql, params)
  File "/data/django_serverauto/env/local/lib/python2.7/site-packages/django/db/backends/util.py", line 69, in execute
    return super(CursorDebugWrapper, self).execute(sql, params)
  File "/data/django_serverauto/env/local/lib/python2.7/site-packages/django/db/backends/util.py", line 53, in execute
    return self.cursor.execute(sql, params)
  File "/data/django_serverauto/env/local/lib/python2.7/site-packages/django/db/utils.py", line 99, in __exit__
    six.reraise(dj_exc_type, dj_exc_value, traceback)
  File "/data/django_serverauto/env/local/lib/python2.7/site-packages/django/db/backends/util.py", line 53, in execute
    return self.cursor.execute(sql, params)
  File "/data/django_serverauto/env/local/lib/python2.7/site-packages/django/db/backends/mysql/base.py", line 124, in execute
    return self.cursor.execute(query, args)
  File "/data/django_serverauto/env/local/lib/python2.7/site-packages/MySQLdb/cursors.py", line 205, in execute
    self.errorhandler(self, exc, value)
  File "/data/django_serverauto/env/local/lib/python2.7/site-packages/MySQLdb/connections.py", line 36, in defaulterrorhandler
    raise errorclass, errorvalue
OperationalError: (1054, "Unknown column 'server_list.server_snmp_on' in 'field list'")
[2015-02-22 12:37:32,378] [ERROR] base : Internal Server Error: /admin/app/serverlist/
Traceback (most recent call last):
  File "/data/django_serverauto/env/local/lib/python2.7/site-packages/django/core/handlers/base.py", line 114, in get_response
    response = wrapped_callback(request, *callback_args, **callback_kwargs)
  File "/data/django_serverauto/env/local/lib/python2.7/site-packages/django/contrib/admin/options.py", line 430, in wrapper
    return self.admin_site.admin_view(view)(*args, **kwargs)
  File "/data/django_serverauto/env/local/lib/python2.7/site-packages/django/utils/decorators.py", line 99, in _wrapped_view
    response = view_func(request, *args, **kwargs)
  File "/data/django_serverauto/env/local/lib/python2.7/site-packages/django/views/decorators/cache.py", line 52, in _wrapped_view_func
    response = view_func(request, *args, **kwargs)
  File "/data/django_serverauto/env/local/lib/python2.7/site-packages/django/contrib/admin/sites.py", line 198, in inner
    return view(request, *args, **kwargs)
  File "/data/django_serverauto/env/local/lib/python2.7/site-packages/django/utils/decorators.py", line 29, in _wrapper
    return bound_func(*args, **kwargs)
  File "/data/django_serverauto/env/local/lib/python2.7/site-packages/django/utils/decorators.py", line 99, in _wrapped_view
    response = view_func(request, *args, **kwargs)
  File "/data/django_serverauto/env/local/lib/python2.7/site-packages/django/utils/decorators.py", line 25, in bound_func
    return func(self, *args2, **kwargs2)
  File "/data/django_serverauto/env/local/lib/python2.7/site-packages/django/contrib/admin/options.py", line 1409, in changelist_view
    'selection_note': _('0 of %(cnt)s selected') % {'cnt': len(cl.result_list)},
  File "/data/django_serverauto/env/local/lib/python2.7/site-packages/django/db/models/query.py", line 77, in __len__
    self._fetch_all()
  File "/data/django_serverauto/env/local/lib/python2.7/site-packages/django/db/models/query.py", line 854, in _fetch_all
    self._result_cache = list(self.iterator())
  File "/data/django_serverauto/env/local/lib/python2.7/site-packages/django/db/models/query.py", line 220, in iterator
    for row in compiler.results_iter():
  File "/data/django_serverauto/env/local/lib/python2.7/site-packages/django/db/models/sql/compiler.py", line 710, in results_iter
    for rows in self.execute_sql(MULTI):
  File "/data/django_serverauto/env/local/lib/python2.7/site-packages/django/db/models/sql/compiler.py", line 781, in execute_sql
    cursor.execute(sql, params)
  File "/data/django_serverauto/env/local/lib/python2.7/site-packages/django/db/backends/util.py", line 69, in execute
    return super(CursorDebugWrapper, self).execute(sql, params)
  File "/data/django_serverauto/env/local/lib/python2.7/site-packages/django/db/backends/util.py", line 53, in execute
    return self.cursor.execute(sql, params)
  File "/data/django_serverauto/env/local/lib/python2.7/site-packages/django/db/utils.py", line 99, in __exit__
    six.reraise(dj_exc_type, dj_exc_value, traceback)
  File "/data/django_serverauto/env/local/lib/python2.7/site-packages/django/db/backends/util.py", line 53, in execute
    return self.cursor.execute(sql, params)
  File "/data/django_serverauto/env/local/lib/python2.7/site-packages/django/db/backends/mysql/base.py", line 124, in execute
    return self.cursor.execute(query, args)
  File "/data/django_serverauto/env/local/lib/python2.7/site-packages/MySQLdb/cursors.py", line 205, in execute
    self.errorhandler(self, exc, value)
  File "/data/django_serverauto/env/local/lib/python2.7/site-packages/MySQLdb/connections.py", line 36, in defaulterrorhandler
    raise errorclass, errorvalue
OperationalError: (1054, "Unknown column 'server_list.server_snmp_on' in 'field list'")
[2015-02-22 12:37:32,378] [ERROR] base : Internal Server Error: /admin/app/serverlist/
Traceback (most recent call last):
  File "/data/django_serverauto/env/local/lib/python2.7/site-packages/django/core/handlers/base.py", line 114, in get_response
    response = wrapped_callback(request, *callback_args, **callback_kwargs)
  File "/data/django_serverauto/env/local/lib/python2.7/site-packages/django/contrib/admin/options.py", line 430, in wrapper
    return self.admin_site.admin_view(view)(*args, **kwargs)
  File "/data/django_serverauto/env/local/lib/python2.7/site-packages/django/utils/decorators.py", line 99, in _wrapped_view
    response = view_func(request, *args, **kwargs)
  File "/data/django_serverauto/env/local/lib/python2.7/site-packages/django/views/decorators/cache.py", line 52, in _wrapped_view_func
    response = view_func(request, *args, **kwargs)
  File "/data/django_serverauto/env/local/lib/python2.7/site-packages/django/contrib/admin/sites.py", line 198, in inner
    return view(request, *args, **kwargs)
  File "/data/django_serverauto/env/local/lib/python2.7/site-packages/django/utils/decorators.py", line 29, in _wrapper
    return bound_func(*args, **kwargs)
  File "/data/django_serverauto/env/local/lib/python2.7/site-packages/django/utils/decorators.py", line 99, in _wrapped_view
    response = view_func(request, *args, **kwargs)
  File "/data/django_serverauto/env/local/lib/python2.7/site-packages/django/utils/decorators.py", line 25, in bound_func
    return func(self, *args2, **kwargs2)
  File "/data/django_serverauto/env/local/lib/python2.7/site-packages/django/contrib/admin/options.py", line 1409, in changelist_view
    'selection_note': _('0 of %(cnt)s selected') % {'cnt': len(cl.result_list)},
  File "/data/django_serverauto/env/local/lib/python2.7/site-packages/django/db/models/query.py", line 77, in __len__
    self._fetch_all()
  File "/data/django_serverauto/env/local/lib/python2.7/site-packages/django/db/models/query.py", line 854, in _fetch_all
    self._result_cache = list(self.iterator())
  File "/data/django_serverauto/env/local/lib/python2.7/site-packages/django/db/models/query.py", line 220, in iterator
    for row in compiler.results_iter():
  File "/data/django_serverauto/env/local/lib/python2.7/site-packages/django/db/models/sql/compiler.py", line 710, in results_iter
    for rows in self.execute_sql(MULTI):
  File "/data/django_serverauto/env/local/lib/python2.7/site-packages/django/db/models/sql/compiler.py", line 781, in execute_sql
    cursor.execute(sql, params)
  File "/data/django_serverauto/env/local/lib/python2.7/site-packages/django/db/backends/util.py", line 69, in execute
    return super(CursorDebugWrapper, self).execute(sql, params)
  File "/data/django_serverauto/env/local/lib/python2.7/site-packages/django/db/backends/util.py", line 53, in execute
    return self.cursor.execute(sql, params)
  File "/data/django_serverauto/env/local/lib/python2.7/site-packages/django/db/utils.py", line 99, in __exit__
    six.reraise(dj_exc_type, dj_exc_value, traceback)
  File "/data/django_serverauto/env/local/lib/python2.7/site-packages/django/db/backends/util.py", line 53, in execute
    return self.cursor.execute(sql, params)
  File "/data/django_serverauto/env/local/lib/python2.7/site-packages/django/db/backends/mysql/base.py", line 124, in execute
    return self.cursor.execute(query, args)
  File "/data/django_serverauto/env/local/lib/python2.7/site-packages/MySQLdb/cursors.py", line 205, in execute
    self.errorhandler(self, exc, value)
  File "/data/django_serverauto/env/local/lib/python2.7/site-packages/MySQLdb/connections.py", line 36, in defaulterrorhandler
    raise errorclass, errorvalue
OperationalError: (1054, "Unknown column 'server_list.server_snmp_on' in 'field list'")
[2015-02-22 12:37:37,034] [ERROR] base : Internal Server Error: /admin/app/serverlist/
Traceback (most recent call last):
  File "/data/django_serverauto/env/local/lib/python2.7/site-packages/django/core/handlers/base.py", line 114, in get_response
    response = wrapped_callback(request, *callback_args, **callback_kwargs)
  File "/data/django_serverauto/env/local/lib/python2.7/site-packages/django/contrib/admin/options.py", line 430, in wrapper
    return self.admin_site.admin_view(view)(*args, **kwargs)
  File "/data/django_serverauto/env/local/lib/python2.7/site-packages/django/utils/decorators.py", line 99, in _wrapped_view
    response = view_func(request, *args, **kwargs)
  File "/data/django_serverauto/env/local/lib/python2.7/site-packages/django/views/decorators/cache.py", line 52, in _wrapped_view_func
    response = view_func(request, *args, **kwargs)
  File "/data/django_serverauto/env/local/lib/python2.7/site-packages/django/contrib/admin/sites.py", line 198, in inner
    return view(request, *args, **kwargs)
  File "/data/django_serverauto/env/local/lib/python2.7/site-packages/django/utils/decorators.py", line 29, in _wrapper
    return bound_func(*args, **kwargs)
  File "/data/django_serverauto/env/local/lib/python2.7/site-packages/django/utils/decorators.py", line 99, in _wrapped_view
    response = view_func(request, *args, **kwargs)
  File "/data/django_serverauto/env/local/lib/python2.7/site-packages/django/utils/decorators.py", line 25, in bound_func
    return func(self, *args2, **kwargs2)
  File "/data/django_serverauto/env/local/lib/python2.7/site-packages/django/contrib/admin/options.py", line 1409, in changelist_view
    'selection_note': _('0 of %(cnt)s selected') % {'cnt': len(cl.result_list)},
  File "/data/django_serverauto/env/local/lib/python2.7/site-packages/django/db/models/query.py", line 77, in __len__
    self._fetch_all()
  File "/data/django_serverauto/env/local/lib/python2.7/site-packages/django/db/models/query.py", line 854, in _fetch_all
    self._result_cache = list(self.iterator())
  File "/data/django_serverauto/env/local/lib/python2.7/site-packages/django/db/models/query.py", line 220, in iterator
    for row in compiler.results_iter():
  File "/data/django_serverauto/env/local/lib/python2.7/site-packages/django/db/models/sql/compiler.py", line 710, in results_iter
    for rows in self.execute_sql(MULTI):
  File "/data/django_serverauto/env/local/lib/python2.7/site-packages/django/db/models/sql/compiler.py", line 781, in execute_sql
    cursor.execute(sql, params)
  File "/data/django_serverauto/env/local/lib/python2.7/site-packages/django/db/backends/util.py", line 69, in execute
    return super(CursorDebugWrapper, self).execute(sql, params)
  File "/data/django_serverauto/env/local/lib/python2.7/site-packages/django/db/backends/util.py", line 53, in execute
    return self.cursor.execute(sql, params)
  File "/data/django_serverauto/env/local/lib/python2.7/site-packages/django/db/utils.py", line 99, in __exit__
    six.reraise(dj_exc_type, dj_exc_value, traceback)
  File "/data/django_serverauto/env/local/lib/python2.7/site-packages/django/db/backends/util.py", line 53, in execute
    return self.cursor.execute(sql, params)
  File "/data/django_serverauto/env/local/lib/python2.7/site-packages/django/db/backends/mysql/base.py", line 124, in execute
    return self.cursor.execute(query, args)
  File "/data/django_serverauto/env/local/lib/python2.7/site-packages/MySQLdb/cursors.py", line 205, in execute
    self.errorhandler(self, exc, value)
  File "/data/django_serverauto/env/local/lib/python2.7/site-packages/MySQLdb/connections.py", line 36, in defaulterrorhandler
    raise errorclass, errorvalue
OperationalError: (1054, "Unknown column 'server_list.server_snmp_on' in 'field list'")
[2015-02-22 12:37:37,034] [ERROR] base : Internal Server Error: /admin/app/serverlist/
Traceback (most recent call last):
  File "/data/django_serverauto/env/local/lib/python2.7/site-packages/django/core/handlers/base.py", line 114, in get_response
    response = wrapped_callback(request, *callback_args, **callback_kwargs)
  File "/data/django_serverauto/env/local/lib/python2.7/site-packages/django/contrib/admin/options.py", line 430, in wrapper
    return self.admin_site.admin_view(view)(*args, **kwargs)
  File "/data/django_serverauto/env/local/lib/python2.7/site-packages/django/utils/decorators.py", line 99, in _wrapped_view
    response = view_func(request, *args, **kwargs)
  File "/data/django_serverauto/env/local/lib/python2.7/site-packages/django/views/decorators/cache.py", line 52, in _wrapped_view_func
    response = view_func(request, *args, **kwargs)
  File "/data/django_serverauto/env/local/lib/python2.7/site-packages/django/contrib/admin/sites.py", line 198, in inner
    return view(request, *args, **kwargs)
  File "/data/django_serverauto/env/local/lib/python2.7/site-packages/django/utils/decorators.py", line 29, in _wrapper
    return bound_func(*args, **kwargs)
  File "/data/django_serverauto/env/local/lib/python2.7/site-packages/django/utils/decorators.py", line 99, in _wrapped_view
    response = view_func(request, *args, **kwargs)
  File "/data/django_serverauto/env/local/lib/python2.7/site-packages/django/utils/decorators.py", line 25, in bound_func
    return func(self, *args2, **kwargs2)
  File "/data/django_serverauto/env/local/lib/python2.7/site-packages/django/contrib/admin/options.py", line 1409, in changelist_view
    'selection_note': _('0 of %(cnt)s selected') % {'cnt': len(cl.result_list)},
  File "/data/django_serverauto/env/local/lib/python2.7/site-packages/django/db/models/query.py", line 77, in __len__
    self._fetch_all()
  File "/data/django_serverauto/env/local/lib/python2.7/site-packages/django/db/models/query.py", line 854, in _fetch_all
    self._result_cache = list(self.iterator())
  File "/data/django_serverauto/env/local/lib/python2.7/site-packages/django/db/models/query.py", line 220, in iterator
    for row in compiler.results_iter():
  File "/data/django_serverauto/env/local/lib/python2.7/site-packages/django/db/models/sql/compiler.py", line 710, in results_iter
    for rows in self.execute_sql(MULTI):
  File "/data/django_serverauto/env/local/lib/python2.7/site-packages/django/db/models/sql/compiler.py", line 781, in execute_sql
    cursor.execute(sql, params)
  File "/data/django_serverauto/env/local/lib/python2.7/site-packages/django/db/backends/util.py", line 69, in execute
    return super(CursorDebugWrapper, self).execute(sql, params)
  File "/data/django_serverauto/env/local/lib/python2.7/site-packages/django/db/backends/util.py", line 53, in execute
    return self.cursor.execute(sql, params)
  File "/data/django_serverauto/env/local/lib/python2.7/site-packages/django/db/utils.py", line 99, in __exit__
    six.reraise(dj_exc_type, dj_exc_value, traceback)
  File "/data/django_serverauto/env/local/lib/python2.7/site-packages/django/db/backends/util.py", line 53, in execute
    return self.cursor.execute(sql, params)
  File "/data/django_serverauto/env/local/lib/python2.7/site-packages/django/db/backends/mysql/base.py", line 124, in execute
    return self.cursor.execute(query, args)
  File "/data/django_serverauto/env/local/lib/python2.7/site-packages/MySQLdb/cursors.py", line 205, in execute
    self.errorhandler(self, exc, value)
  File "/data/django_serverauto/env/local/lib/python2.7/site-packages/MySQLdb/connections.py", line 36, in defaulterrorhandler
    raise errorclass, errorvalue
OperationalError: (1054, "Unknown column 'server_list.server_snmp_on' in 'field list'")
[2015-02-22 12:46:26,482] [INFO] views : index
[2015-02-22 13:20:15,706] [INFO] views : index
[2015-02-22 13:44:49,589] [INFO] views : index
[2015-02-22 13:54:19,100] [INFO] views : index
[2015-02-22 14:16:16,769] [INFO] views : index
[2015-02-25 16:29:52,463] [ERROR] base : Internal Server Error: /
Traceback (most recent call last):
  File "/data/django_serverauto/env/local/lib/python2.7/site-packages/django/core/handlers/base.py", line 114, in get_response
    response = wrapped_callback(request, *callback_args, **callback_kwargs)
  File "/data/django_serverauto/ServerAutoSys/app/views.py", line 33, in login
    if request.user.is_authenticated():
  File "/data/django_serverauto/env/local/lib/python2.7/site-packages/django/utils/functional.py", line 213, in inner
    self._setup()
  File "/data/django_serverauto/env/local/lib/python2.7/site-packages/django/utils/functional.py", line 298, in _setup
    self._wrapped = self._setupfunc()
  File "/data/django_serverauto/env/local/lib/python2.7/site-packages/django/contrib/auth/middleware.py", line 18, in <lambda>
    request.user = SimpleLazyObject(lambda: get_user(request))
  File "/data/django_serverauto/env/local/lib/python2.7/site-packages/django/contrib/auth/middleware.py", line 10, in get_user
    request._cached_user = auth.get_user(request)
  File "/data/django_serverauto/env/local/lib/python2.7/site-packages/django/contrib/auth/__init__.py", line 133, in get_user
    user_id = request.session[SESSION_KEY]
  File "/data/django_serverauto/env/local/lib/python2.7/site-packages/django/contrib/sessions/backends/base.py", line 47, in __getitem__
    return self._session[key]
  File "/data/django_serverauto/env/local/lib/python2.7/site-packages/django/contrib/sessions/backends/base.py", line 173, in _get_session
    self._session_cache = self.load()
  File "/data/django_serverauto/env/local/lib/python2.7/site-packages/django/contrib/sessions/backends/db.py", line 20, in load
    expire_date__gt=timezone.now()
  File "/data/django_serverauto/env/local/lib/python2.7/site-packages/django/db/models/manager.py", line 151, in get
    return self.get_queryset().get(*args, **kwargs)
  File "/data/django_serverauto/env/local/lib/python2.7/site-packages/django/db/models/query.py", line 301, in get
    num = len(clone)
  File "/data/django_serverauto/env/local/lib/python2.7/site-packages/django/db/models/query.py", line 77, in __len__
    self._fetch_all()
  File "/data/django_serverauto/env/local/lib/python2.7/site-packages/django/db/models/query.py", line 854, in _fetch_all
    self._result_cache = list(self.iterator())
  File "/data/django_serverauto/env/local/lib/python2.7/site-packages/django/db/models/query.py", line 220, in iterator
    for row in compiler.results_iter():
  File "/data/django_serverauto/env/local/lib/python2.7/site-packages/django/db/models/sql/compiler.py", line 710, in results_iter
    for rows in self.execute_sql(MULTI):
  File "/data/django_serverauto/env/local/lib/python2.7/site-packages/django/db/models/sql/compiler.py", line 780, in execute_sql
    cursor = self.connection.cursor()
  File "/data/django_serverauto/env/local/lib/python2.7/site-packages/django/db/backends/__init__.py", line 157, in cursor
    cursor = self.make_debug_cursor(self._cursor())
  File "/data/django_serverauto/env/local/lib/python2.7/site-packages/django/db/backends/__init__.py", line 129, in _cursor
    self.ensure_connection()
  File "/data/django_serverauto/env/local/lib/python2.7/site-packages/django/db/backends/__init__.py", line 124, in ensure_connection
    self.connect()
  File "/data/django_serverauto/env/local/lib/python2.7/site-packages/django/db/utils.py", line 99, in __exit__
    six.reraise(dj_exc_type, dj_exc_value, traceback)
  File "/data/django_serverauto/env/local/lib/python2.7/site-packages/django/db/backends/__init__.py", line 124, in ensure_connection
    self.connect()
  File "/data/django_serverauto/env/local/lib/python2.7/site-packages/django/db/backends/__init__.py", line 112, in connect
    self.connection = self.get_new_connection(conn_params)
  File "/data/django_serverauto/env/local/lib/python2.7/site-packages/django/db/backends/mysql/base.py", line 435, in get_new_connection
    conn = Database.connect(**conn_params)
  File "/data/django_serverauto/env/local/lib/python2.7/site-packages/MySQLdb/__init__.py", line 81, in Connect
    return Connection(*args, **kwargs)
  File "/data/django_serverauto/env/local/lib/python2.7/site-packages/MySQLdb/connections.py", line 193, in __init__
    super(Connection, self).__init__(*args, **kwargs2)
OperationalError: (2003, "Can't connect to MySQL server on '127.0.0.1' (111)")
[2015-02-25 16:29:52,463] [ERROR] base : Internal Server Error: /
Traceback (most recent call last):
  File "/data/django_serverauto/env/local/lib/python2.7/site-packages/django/core/handlers/base.py", line 114, in get_response
    response = wrapped_callback(request, *callback_args, **callback_kwargs)
  File "/data/django_serverauto/ServerAutoSys/app/views.py", line 33, in login
    if request.user.is_authenticated():
  File "/data/django_serverauto/env/local/lib/python2.7/site-packages/django/utils/functional.py", line 213, in inner
    self._setup()
  File "/data/django_serverauto/env/local/lib/python2.7/site-packages/django/utils/functional.py", line 298, in _setup
    self._wrapped = self._setupfunc()
  File "/data/django_serverauto/env/local/lib/python2.7/site-packages/django/contrib/auth/middleware.py", line 18, in <lambda>
    request.user = SimpleLazyObject(lambda: get_user(request))
  File "/data/django_serverauto/env/local/lib/python2.7/site-packages/django/contrib/auth/middleware.py", line 10, in get_user
    request._cached_user = auth.get_user(request)
  File "/data/django_serverauto/env/local/lib/python2.7/site-packages/django/contrib/auth/__init__.py", line 133, in get_user
    user_id = request.session[SESSION_KEY]
  File "/data/django_serverauto/env/local/lib/python2.7/site-packages/django/contrib/sessions/backends/base.py", line 47, in __getitem__
    return self._session[key]
  File "/data/django_serverauto/env/local/lib/python2.7/site-packages/django/contrib/sessions/backends/base.py", line 173, in _get_session
    self._session_cache = self.load()
  File "/data/django_serverauto/env/local/lib/python2.7/site-packages/django/contrib/sessions/backends/db.py", line 20, in load
    expire_date__gt=timezone.now()
  File "/data/django_serverauto/env/local/lib/python2.7/site-packages/django/db/models/manager.py", line 151, in get
    return self.get_queryset().get(*args, **kwargs)
  File "/data/django_serverauto/env/local/lib/python2.7/site-packages/django/db/models/query.py", line 301, in get
    num = len(clone)
  File "/data/django_serverauto/env/local/lib/python2.7/site-packages/django/db/models/query.py", line 77, in __len__
    self._fetch_all()
  File "/data/django_serverauto/env/local/lib/python2.7/site-packages/django/db/models/query.py", line 854, in _fetch_all
    self._result_cache = list(self.iterator())
  File "/data/django_serverauto/env/local/lib/python2.7/site-packages/django/db/models/query.py", line 220, in iterator
    for row in compiler.results_iter():
  File "/data/django_serverauto/env/local/lib/python2.7/site-packages/django/db/models/sql/compiler.py", line 710, in results_iter
    for rows in self.execute_sql(MULTI):
  File "/data/django_serverauto/env/local/lib/python2.7/site-packages/django/db/models/sql/compiler.py", line 780, in execute_sql
    cursor = self.connection.cursor()
  File "/data/django_serverauto/env/local/lib/python2.7/site-packages/django/db/backends/__init__.py", line 157, in cursor
    cursor = self.make_debug_cursor(self._cursor())
  File "/data/django_serverauto/env/local/lib/python2.7/site-packages/django/db/backends/__init__.py", line 129, in _cursor
    self.ensure_connection()
  File "/data/django_serverauto/env/local/lib/python2.7/site-packages/django/db/backends/__init__.py", line 124, in ensure_connection
    self.connect()
  File "/data/django_serverauto/env/local/lib/python2.7/site-packages/django/db/utils.py", line 99, in __exit__
    six.reraise(dj_exc_type, dj_exc_value, traceback)
  File "/data/django_serverauto/env/local/lib/python2.7/site-packages/django/db/backends/__init__.py", line 124, in ensure_connection
    self.connect()
  File "/data/django_serverauto/env/local/lib/python2.7/site-packages/django/db/backends/__init__.py", line 112, in connect
    self.connection = self.get_new_connection(conn_params)
  File "/data/django_serverauto/env/local/lib/python2.7/site-packages/django/db/backends/mysql/base.py", line 435, in get_new_connection
    conn = Database.connect(**conn_params)
  File "/data/django_serverauto/env/local/lib/python2.7/site-packages/MySQLdb/__init__.py", line 81, in Connect
    return Connection(*args, **kwargs)
  File "/data/django_serverauto/env/local/lib/python2.7/site-packages/MySQLdb/connections.py", line 193, in __init__
    super(Connection, self).__init__(*args, **kwargs2)
OperationalError: (2003, "Can't connect to MySQL server on '127.0.0.1' (111)")
[2015-02-25 16:29:52,882] [ERROR] base : Internal Server Error: /
Traceback (most recent call last):
  File "/data/django_serverauto/env/local/lib/python2.7/site-packages/django/core/handlers/base.py", line 114, in get_response
    response = wrapped_callback(request, *callback_args, **callback_kwargs)
  File "/data/django_serverauto/ServerAutoSys/app/views.py", line 33, in login
    if request.user.is_authenticated():
  File "/data/django_serverauto/env/local/lib/python2.7/site-packages/django/utils/functional.py", line 213, in inner
    self._setup()
  File "/data/django_serverauto/env/local/lib/python2.7/site-packages/django/utils/functional.py", line 298, in _setup
    self._wrapped = self._setupfunc()
  File "/data/django_serverauto/env/local/lib/python2.7/site-packages/django/contrib/auth/middleware.py", line 18, in <lambda>
    request.user = SimpleLazyObject(lambda: get_user(request))
  File "/data/django_serverauto/env/local/lib/python2.7/site-packages/django/contrib/auth/middleware.py", line 10, in get_user
    request._cached_user = auth.get_user(request)
  File "/data/django_serverauto/env/local/lib/python2.7/site-packages/django/contrib/auth/__init__.py", line 133, in get_user
    user_id = request.session[SESSION_KEY]
  File "/data/django_serverauto/env/local/lib/python2.7/site-packages/django/contrib/sessions/backends/base.py", line 47, in __getitem__
    return self._session[key]
  File "/data/django_serverauto/env/local/lib/python2.7/site-packages/django/contrib/sessions/backends/base.py", line 173, in _get_session
    self._session_cache = self.load()
  File "/data/django_serverauto/env/local/lib/python2.7/site-packages/django/contrib/sessions/backends/db.py", line 20, in load
    expire_date__gt=timezone.now()
  File "/data/django_serverauto/env/local/lib/python2.7/site-packages/django/db/models/manager.py", line 151, in get
    return self.get_queryset().get(*args, **kwargs)
  File "/data/django_serverauto/env/local/lib/python2.7/site-packages/django/db/models/query.py", line 301, in get
    num = len(clone)
  File "/data/django_serverauto/env/local/lib/python2.7/site-packages/django/db/models/query.py", line 77, in __len__
    self._fetch_all()
  File "/data/django_serverauto/env/local/lib/python2.7/site-packages/django/db/models/query.py", line 854, in _fetch_all
    self._result_cache = list(self.iterator())
  File "/data/django_serverauto/env/local/lib/python2.7/site-packages/django/db/models/query.py", line 220, in iterator
    for row in compiler.results_iter():
  File "/data/django_serverauto/env/local/lib/python2.7/site-packages/django/db/models/sql/compiler.py", line 710, in results_iter
    for rows in self.execute_sql(MULTI):
  File "/data/django_serverauto/env/local/lib/python2.7/site-packages/django/db/models/sql/compiler.py", line 780, in execute_sql
    cursor = self.connection.cursor()
  File "/data/django_serverauto/env/local/lib/python2.7/site-packages/django/db/backends/__init__.py", line 157, in cursor
    cursor = self.make_debug_cursor(self._cursor())
  File "/data/django_serverauto/env/local/lib/python2.7/site-packages/django/db/backends/__init__.py", line 129, in _cursor
    self.ensure_connection()
  File "/data/django_serverauto/env/local/lib/python2.7/site-packages/django/db/backends/__init__.py", line 124, in ensure_connection
    self.connect()
  File "/data/django_serverauto/env/local/lib/python2.7/site-packages/django/db/utils.py", line 99, in __exit__
    six.reraise(dj_exc_type, dj_exc_value, traceback)
  File "/data/django_serverauto/env/local/lib/python2.7/site-packages/django/db/backends/__init__.py", line 124, in ensure_connection
    self.connect()
  File "/data/django_serverauto/env/local/lib/python2.7/site-packages/django/db/backends/__init__.py", line 112, in connect
    self.connection = self.get_new_connection(conn_params)
  File "/data/django_serverauto/env/local/lib/python2.7/site-packages/django/db/backends/mysql/base.py", line 435, in get_new_connection
    conn = Database.connect(**conn_params)
  File "/data/django_serverauto/env/local/lib/python2.7/site-packages/MySQLdb/__init__.py", line 81, in Connect
    return Connection(*args, **kwargs)
  File "/data/django_serverauto/env/local/lib/python2.7/site-packages/MySQLdb/connections.py", line 193, in __init__
    super(Connection, self).__init__(*args, **kwargs2)
OperationalError: (2003, "Can't connect to MySQL server on '127.0.0.1' (111)")
[2015-02-25 16:29:52,882] [ERROR] base : Internal Server Error: /
Traceback (most recent call last):
  File "/data/django_serverauto/env/local/lib/python2.7/site-packages/django/core/handlers/base.py", line 114, in get_response
    response = wrapped_callback(request, *callback_args, **callback_kwargs)
  File "/data/django_serverauto/ServerAutoSys/app/views.py", line 33, in login
    if request.user.is_authenticated():
  File "/data/django_serverauto/env/local/lib/python2.7/site-packages/django/utils/functional.py", line 213, in inner
    self._setup()
  File "/data/django_serverauto/env/local/lib/python2.7/site-packages/django/utils/functional.py", line 298, in _setup
    self._wrapped = self._setupfunc()
  File "/data/django_serverauto/env/local/lib/python2.7/site-packages/django/contrib/auth/middleware.py", line 18, in <lambda>
    request.user = SimpleLazyObject(lambda: get_user(request))
  File "/data/django_serverauto/env/local/lib/python2.7/site-packages/django/contrib/auth/middleware.py", line 10, in get_user
    request._cached_user = auth.get_user(request)
  File "/data/django_serverauto/env/local/lib/python2.7/site-packages/django/contrib/auth/__init__.py", line 133, in get_user
    user_id = request.session[SESSION_KEY]
  File "/data/django_serverauto/env/local/lib/python2.7/site-packages/django/contrib/sessions/backends/base.py", line 47, in __getitem__
    return self._session[key]
  File "/data/django_serverauto/env/local/lib/python2.7/site-packages/django/contrib/sessions/backends/base.py", line 173, in _get_session
    self._session_cache = self.load()
  File "/data/django_serverauto/env/local/lib/python2.7/site-packages/django/contrib/sessions/backends/db.py", line 20, in load
    expire_date__gt=timezone.now()
  File "/data/django_serverauto/env/local/lib/python2.7/site-packages/django/db/models/manager.py", line 151, in get
    return self.get_queryset().get(*args, **kwargs)
  File "/data/django_serverauto/env/local/lib/python2.7/site-packages/django/db/models/query.py", line 301, in get
    num = len(clone)
  File "/data/django_serverauto/env/local/lib/python2.7/site-packages/django/db/models/query.py", line 77, in __len__
    self._fetch_all()
  File "/data/django_serverauto/env/local/lib/python2.7/site-packages/django/db/models/query.py", line 854, in _fetch_all
    self._result_cache = list(self.iterator())
  File "/data/django_serverauto/env/local/lib/python2.7/site-packages/django/db/models/query.py", line 220, in iterator
    for row in compiler.results_iter():
  File "/data/django_serverauto/env/local/lib/python2.7/site-packages/django/db/models/sql/compiler.py", line 710, in results_iter
    for rows in self.execute_sql(MULTI):
  File "/data/django_serverauto/env/local/lib/python2.7/site-packages/django/db/models/sql/compiler.py", line 780, in execute_sql
    cursor = self.connection.cursor()
  File "/data/django_serverauto/env/local/lib/python2.7/site-packages/django/db/backends/__init__.py", line 157, in cursor
    cursor = self.make_debug_cursor(self._cursor())
  File "/data/django_serverauto/env/local/lib/python2.7/site-packages/django/db/backends/__init__.py", line 129, in _cursor
    self.ensure_connection()
  File "/data/django_serverauto/env/local/lib/python2.7/site-packages/django/db/backends/__init__.py", line 124, in ensure_connection
    self.connect()
  File "/data/django_serverauto/env/local/lib/python2.7/site-packages/django/db/utils.py", line 99, in __exit__
    six.reraise(dj_exc_type, dj_exc_value, traceback)
  File "/data/django_serverauto/env/local/lib/python2.7/site-packages/django/db/backends/__init__.py", line 124, in ensure_connection
    self.connect()
  File "/data/django_serverauto/env/local/lib/python2.7/site-packages/django/db/backends/__init__.py", line 112, in connect
    self.connection = self.get_new_connection(conn_params)
  File "/data/django_serverauto/env/local/lib/python2.7/site-packages/django/db/backends/mysql/base.py", line 435, in get_new_connection
    conn = Database.connect(**conn_params)
  File "/data/django_serverauto/env/local/lib/python2.7/site-packages/MySQLdb/__init__.py", line 81, in Connect
    return Connection(*args, **kwargs)
  File "/data/django_serverauto/env/local/lib/python2.7/site-packages/MySQLdb/connections.py", line 193, in __init__
    super(Connection, self).__init__(*args, **kwargs2)
OperationalError: (2003, "Can't connect to MySQL server on '127.0.0.1' (111)")
[2015-02-25 16:30:19,671] [INFO] views : index
[2015-02-25 21:35:13,213] [INFO] views : index
[2015-03-03 21:40:16,181] [ERROR] base : Internal Server Error: /
Traceback (most recent call last):
  File "/data/django_serverauto/env/local/lib/python2.7/site-packages/django/core/handlers/base.py", line 114, in get_response
    response = wrapped_callback(request, *callback_args, **callback_kwargs)
  File "/data/django_serverauto/ServerAutoSys/app/views.py", line 33, in login
    if request.user.is_authenticated():
  File "/data/django_serverauto/env/local/lib/python2.7/site-packages/django/utils/functional.py", line 213, in inner
    self._setup()
  File "/data/django_serverauto/env/local/lib/python2.7/site-packages/django/utils/functional.py", line 298, in _setup
    self._wrapped = self._setupfunc()
  File "/data/django_serverauto/env/local/lib/python2.7/site-packages/django/contrib/auth/middleware.py", line 18, in <lambda>
    request.user = SimpleLazyObject(lambda: get_user(request))
  File "/data/django_serverauto/env/local/lib/python2.7/site-packages/django/contrib/auth/middleware.py", line 10, in get_user
    request._cached_user = auth.get_user(request)
  File "/data/django_serverauto/env/local/lib/python2.7/site-packages/django/contrib/auth/__init__.py", line 133, in get_user
    user_id = request.session[SESSION_KEY]
  File "/data/django_serverauto/env/local/lib/python2.7/site-packages/django/contrib/sessions/backends/base.py", line 47, in __getitem__
    return self._session[key]
  File "/data/django_serverauto/env/local/lib/python2.7/site-packages/django/contrib/sessions/backends/base.py", line 173, in _get_session
    self._session_cache = self.load()
  File "/data/django_serverauto/env/local/lib/python2.7/site-packages/django/contrib/sessions/backends/db.py", line 20, in load
    expire_date__gt=timezone.now()
  File "/data/django_serverauto/env/local/lib/python2.7/site-packages/django/db/models/manager.py", line 151, in get
    return self.get_queryset().get(*args, **kwargs)
  File "/data/django_serverauto/env/local/lib/python2.7/site-packages/django/db/models/query.py", line 301, in get
    num = len(clone)
  File "/data/django_serverauto/env/local/lib/python2.7/site-packages/django/db/models/query.py", line 77, in __len__
    self._fetch_all()
  File "/data/django_serverauto/env/local/lib/python2.7/site-packages/django/db/models/query.py", line 854, in _fetch_all
    self._result_cache = list(self.iterator())
  File "/data/django_serverauto/env/local/lib/python2.7/site-packages/django/db/models/query.py", line 220, in iterator
    for row in compiler.results_iter():
  File "/data/django_serverauto/env/local/lib/python2.7/site-packages/django/db/models/sql/compiler.py", line 710, in results_iter
    for rows in self.execute_sql(MULTI):
  File "/data/django_serverauto/env/local/lib/python2.7/site-packages/django/db/models/sql/compiler.py", line 780, in execute_sql
    cursor = self.connection.cursor()
  File "/data/django_serverauto/env/local/lib/python2.7/site-packages/django/db/backends/__init__.py", line 157, in cursor
    cursor = self.make_debug_cursor(self._cursor())
  File "/data/django_serverauto/env/local/lib/python2.7/site-packages/django/db/backends/__init__.py", line 129, in _cursor
    self.ensure_connection()
  File "/data/django_serverauto/env/local/lib/python2.7/site-packages/django/db/backends/__init__.py", line 124, in ensure_connection
    self.connect()
  File "/data/django_serverauto/env/local/lib/python2.7/site-packages/django/db/utils.py", line 99, in __exit__
    six.reraise(dj_exc_type, dj_exc_value, traceback)
  File "/data/django_serverauto/env/local/lib/python2.7/site-packages/django/db/backends/__init__.py", line 124, in ensure_connection
    self.connect()
  File "/data/django_serverauto/env/local/lib/python2.7/site-packages/django/db/backends/__init__.py", line 112, in connect
    self.connection = self.get_new_connection(conn_params)
  File "/data/django_serverauto/env/local/lib/python2.7/site-packages/django/db/backends/mysql/base.py", line 435, in get_new_connection
    conn = Database.connect(**conn_params)
  File "/data/django_serverauto/env/local/lib/python2.7/site-packages/MySQLdb/__init__.py", line 81, in Connect
    return Connection(*args, **kwargs)
  File "/data/django_serverauto/env/local/lib/python2.7/site-packages/MySQLdb/connections.py", line 193, in __init__
    super(Connection, self).__init__(*args, **kwargs2)
OperationalError: (2003, "Can't connect to MySQL server on '127.0.0.1' (111)")
[2015-03-03 21:40:16,181] [ERROR] base : Internal Server Error: /
Traceback (most recent call last):
  File "/data/django_serverauto/env/local/lib/python2.7/site-packages/django/core/handlers/base.py", line 114, in get_response
    response = wrapped_callback(request, *callback_args, **callback_kwargs)
  File "/data/django_serverauto/ServerAutoSys/app/views.py", line 33, in login
    if request.user.is_authenticated():
  File "/data/django_serverauto/env/local/lib/python2.7/site-packages/django/utils/functional.py", line 213, in inner
    self._setup()
  File "/data/django_serverauto/env/local/lib/python2.7/site-packages/django/utils/functional.py", line 298, in _setup
    self._wrapped = self._setupfunc()
  File "/data/django_serverauto/env/local/lib/python2.7/site-packages/django/contrib/auth/middleware.py", line 18, in <lambda>
    request.user = SimpleLazyObject(lambda: get_user(request))
  File "/data/django_serverauto/env/local/lib/python2.7/site-packages/django/contrib/auth/middleware.py", line 10, in get_user
    request._cached_user = auth.get_user(request)
  File "/data/django_serverauto/env/local/lib/python2.7/site-packages/django/contrib/auth/__init__.py", line 133, in get_user
    user_id = request.session[SESSION_KEY]
  File "/data/django_serverauto/env/local/lib/python2.7/site-packages/django/contrib/sessions/backends/base.py", line 47, in __getitem__
    return self._session[key]
  File "/data/django_serverauto/env/local/lib/python2.7/site-packages/django/contrib/sessions/backends/base.py", line 173, in _get_session
    self._session_cache = self.load()
  File "/data/django_serverauto/env/local/lib/python2.7/site-packages/django/contrib/sessions/backends/db.py", line 20, in load
    expire_date__gt=timezone.now()
  File "/data/django_serverauto/env/local/lib/python2.7/site-packages/django/db/models/manager.py", line 151, in get
    return self.get_queryset().get(*args, **kwargs)
  File "/data/django_serverauto/env/local/lib/python2.7/site-packages/django/db/models/query.py", line 301, in get
    num = len(clone)
  File "/data/django_serverauto/env/local/lib/python2.7/site-packages/django/db/models/query.py", line 77, in __len__
    self._fetch_all()
  File "/data/django_serverauto/env/local/lib/python2.7/site-packages/django/db/models/query.py", line 854, in _fetch_all
    self._result_cache = list(self.iterator())
  File "/data/django_serverauto/env/local/lib/python2.7/site-packages/django/db/models/query.py", line 220, in iterator
    for row in compiler.results_iter():
  File "/data/django_serverauto/env/local/lib/python2.7/site-packages/django/db/models/sql/compiler.py", line 710, in results_iter
    for rows in self.execute_sql(MULTI):
  File "/data/django_serverauto/env/local/lib/python2.7/site-packages/django/db/models/sql/compiler.py", line 780, in execute_sql
    cursor = self.connection.cursor()
  File "/data/django_serverauto/env/local/lib/python2.7/site-packages/django/db/backends/__init__.py", line 157, in cursor
    cursor = self.make_debug_cursor(self._cursor())
  File "/data/django_serverauto/env/local/lib/python2.7/site-packages/django/db/backends/__init__.py", line 129, in _cursor
    self.ensure_connection()
  File "/data/django_serverauto/env/local/lib/python2.7/site-packages/django/db/backends/__init__.py", line 124, in ensure_connection
    self.connect()
  File "/data/django_serverauto/env/local/lib/python2.7/site-packages/django/db/utils.py", line 99, in __exit__
    six.reraise(dj_exc_type, dj_exc_value, traceback)
  File "/data/django_serverauto/env/local/lib/python2.7/site-packages/django/db/backends/__init__.py", line 124, in ensure_connection
    self.connect()
  File "/data/django_serverauto/env/local/lib/python2.7/site-packages/django/db/backends/__init__.py", line 112, in connect
    self.connection = self.get_new_connection(conn_params)
  File "/data/django_serverauto/env/local/lib/python2.7/site-packages/django/db/backends/mysql/base.py", line 435, in get_new_connection
    conn = Database.connect(**conn_params)
  File "/data/django_serverauto/env/local/lib/python2.7/site-packages/MySQLdb/__init__.py", line 81, in Connect
    return Connection(*args, **kwargs)
  File "/data/django_serverauto/env/local/lib/python2.7/site-packages/MySQLdb/connections.py", line 193, in __init__
    super(Connection, self).__init__(*args, **kwargs2)
OperationalError: (2003, "Can't connect to MySQL server on '127.0.0.1' (111)")
[2015-03-03 21:40:16,384] [ERROR] base : Internal Server Error: /
Traceback (most recent call last):
  File "/data/django_serverauto/env/local/lib/python2.7/site-packages/django/core/handlers/base.py", line 114, in get_response
    response = wrapped_callback(request, *callback_args, **callback_kwargs)
  File "/data/django_serverauto/ServerAutoSys/app/views.py", line 33, in login
    if request.user.is_authenticated():
  File "/data/django_serverauto/env/local/lib/python2.7/site-packages/django/utils/functional.py", line 213, in inner
    self._setup()
  File "/data/django_serverauto/env/local/lib/python2.7/site-packages/django/utils/functional.py", line 298, in _setup
    self._wrapped = self._setupfunc()
  File "/data/django_serverauto/env/local/lib/python2.7/site-packages/django/contrib/auth/middleware.py", line 18, in <lambda>
    request.user = SimpleLazyObject(lambda: get_user(request))
  File "/data/django_serverauto/env/local/lib/python2.7/site-packages/django/contrib/auth/middleware.py", line 10, in get_user
    request._cached_user = auth.get_user(request)
  File "/data/django_serverauto/env/local/lib/python2.7/site-packages/django/contrib/auth/__init__.py", line 133, in get_user
    user_id = request.session[SESSION_KEY]
  File "/data/django_serverauto/env/local/lib/python2.7/site-packages/django/contrib/sessions/backends/base.py", line 47, in __getitem__
    return self._session[key]
  File "/data/django_serverauto/env/local/lib/python2.7/site-packages/django/contrib/sessions/backends/base.py", line 173, in _get_session
    self._session_cache = self.load()
  File "/data/django_serverauto/env/local/lib/python2.7/site-packages/django/contrib/sessions/backends/db.py", line 20, in load
    expire_date__gt=timezone.now()
  File "/data/django_serverauto/env/local/lib/python2.7/site-packages/django/db/models/manager.py", line 151, in get
    return self.get_queryset().get(*args, **kwargs)
  File "/data/django_serverauto/env/local/lib/python2.7/site-packages/django/db/models/query.py", line 301, in get
    num = len(clone)
  File "/data/django_serverauto/env/local/lib/python2.7/site-packages/django/db/models/query.py", line 77, in __len__
    self._fetch_all()
  File "/data/django_serverauto/env/local/lib/python2.7/site-packages/django/db/models/query.py", line 854, in _fetch_all
    self._result_cache = list(self.iterator())
  File "/data/django_serverauto/env/local/lib/python2.7/site-packages/django/db/models/query.py", line 220, in iterator
    for row in compiler.results_iter():
  File "/data/django_serverauto/env/local/lib/python2.7/site-packages/django/db/models/sql/compiler.py", line 710, in results_iter
    for rows in self.execute_sql(MULTI):
  File "/data/django_serverauto/env/local/lib/python2.7/site-packages/django/db/models/sql/compiler.py", line 780, in execute_sql
    cursor = self.connection.cursor()
  File "/data/django_serverauto/env/local/lib/python2.7/site-packages/django/db/backends/__init__.py", line 157, in cursor
    cursor = self.make_debug_cursor(self._cursor())
  File "/data/django_serverauto/env/local/lib/python2.7/site-packages/django/db/backends/__init__.py", line 129, in _cursor
    self.ensure_connection()
  File "/data/django_serverauto/env/local/lib/python2.7/site-packages/django/db/backends/__init__.py", line 124, in ensure_connection
    self.connect()
  File "/data/django_serverauto/env/local/lib/python2.7/site-packages/django/db/utils.py", line 99, in __exit__
    six.reraise(dj_exc_type, dj_exc_value, traceback)
  File "/data/django_serverauto/env/local/lib/python2.7/site-packages/django/db/backends/__init__.py", line 124, in ensure_connection
    self.connect()
  File "/data/django_serverauto/env/local/lib/python2.7/site-packages/django/db/backends/__init__.py", line 112, in connect
    self.connection = self.get_new_connection(conn_params)
  File "/data/django_serverauto/env/local/lib/python2.7/site-packages/django/db/backends/mysql/base.py", line 435, in get_new_connection
    conn = Database.connect(**conn_params)
  File "/data/django_serverauto/env/local/lib/python2.7/site-packages/MySQLdb/__init__.py", line 81, in Connect
    return Connection(*args, **kwargs)
  File "/data/django_serverauto/env/local/lib/python2.7/site-packages/MySQLdb/connections.py", line 193, in __init__
    super(Connection, self).__init__(*args, **kwargs2)
OperationalError: (2003, "Can't connect to MySQL server on '127.0.0.1' (111)")
[2015-03-03 21:40:16,384] [ERROR] base : Internal Server Error: /
Traceback (most recent call last):
  File "/data/django_serverauto/env/local/lib/python2.7/site-packages/django/core/handlers/base.py", line 114, in get_response
    response = wrapped_callback(request, *callback_args, **callback_kwargs)
  File "/data/django_serverauto/ServerAutoSys/app/views.py", line 33, in login
    if request.user.is_authenticated():
  File "/data/django_serverauto/env/local/lib/python2.7/site-packages/django/utils/functional.py", line 213, in inner
    self._setup()
  File "/data/django_serverauto/env/local/lib/python2.7/site-packages/django/utils/functional.py", line 298, in _setup
    self._wrapped = self._setupfunc()
  File "/data/django_serverauto/env/local/lib/python2.7/site-packages/django/contrib/auth/middleware.py", line 18, in <lambda>
    request.user = SimpleLazyObject(lambda: get_user(request))
  File "/data/django_serverauto/env/local/lib/python2.7/site-packages/django/contrib/auth/middleware.py", line 10, in get_user
    request._cached_user = auth.get_user(request)
  File "/data/django_serverauto/env/local/lib/python2.7/site-packages/django/contrib/auth/__init__.py", line 133, in get_user
    user_id = request.session[SESSION_KEY]
  File "/data/django_serverauto/env/local/lib/python2.7/site-packages/django/contrib/sessions/backends/base.py", line 47, in __getitem__
    return self._session[key]
  File "/data/django_serverauto/env/local/lib/python2.7/site-packages/django/contrib/sessions/backends/base.py", line 173, in _get_session
    self._session_cache = self.load()
  File "/data/django_serverauto/env/local/lib/python2.7/site-packages/django/contrib/sessions/backends/db.py", line 20, in load
    expire_date__gt=timezone.now()
  File "/data/django_serverauto/env/local/lib/python2.7/site-packages/django/db/models/manager.py", line 151, in get
    return self.get_queryset().get(*args, **kwargs)
  File "/data/django_serverauto/env/local/lib/python2.7/site-packages/django/db/models/query.py", line 301, in get
    num = len(clone)
  File "/data/django_serverauto/env/local/lib/python2.7/site-packages/django/db/models/query.py", line 77, in __len__
    self._fetch_all()
  File "/data/django_serverauto/env/local/lib/python2.7/site-packages/django/db/models/query.py", line 854, in _fetch_all
    self._result_cache = list(self.iterator())
  File "/data/django_serverauto/env/local/lib/python2.7/site-packages/django/db/models/query.py", line 220, in iterator
    for row in compiler.results_iter():
  File "/data/django_serverauto/env/local/lib/python2.7/site-packages/django/db/models/sql/compiler.py", line 710, in results_iter
    for rows in self.execute_sql(MULTI):
  File "/data/django_serverauto/env/local/lib/python2.7/site-packages/django/db/models/sql/compiler.py", line 780, in execute_sql
    cursor = self.connection.cursor()
  File "/data/django_serverauto/env/local/lib/python2.7/site-packages/django/db/backends/__init__.py", line 157, in cursor
    cursor = self.make_debug_cursor(self._cursor())
  File "/data/django_serverauto/env/local/lib/python2.7/site-packages/django/db/backends/__init__.py", line 129, in _cursor
    self.ensure_connection()
  File "/data/django_serverauto/env/local/lib/python2.7/site-packages/django/db/backends/__init__.py", line 124, in ensure_connection
    self.connect()
  File "/data/django_serverauto/env/local/lib/python2.7/site-packages/django/db/utils.py", line 99, in __exit__
    six.reraise(dj_exc_type, dj_exc_value, traceback)
  File "/data/django_serverauto/env/local/lib/python2.7/site-packages/django/db/backends/__init__.py", line 124, in ensure_connection
    self.connect()
  File "/data/django_serverauto/env/local/lib/python2.7/site-packages/django/db/backends/__init__.py", line 112, in connect
    self.connection = self.get_new_connection(conn_params)
  File "/data/django_serverauto/env/local/lib/python2.7/site-packages/django/db/backends/mysql/base.py", line 435, in get_new_connection
    conn = Database.connect(**conn_params)
  File "/data/django_serverauto/env/local/lib/python2.7/site-packages/MySQLdb/__init__.py", line 81, in Connect
    return Connection(*args, **kwargs)
  File "/data/django_serverauto/env/local/lib/python2.7/site-packages/MySQLdb/connections.py", line 193, in __init__
    super(Connection, self).__init__(*args, **kwargs2)
OperationalError: (2003, "Can't connect to MySQL server on '127.0.0.1' (111)")
[2015-03-03 21:40:30,127] [INFO] views : index
[2015-03-03 22:26:30,411] [INFO] views : index
[2015-03-03 23:02:15,971] [ERROR] base : Internal Server Error: /app/getMemInfo/
Traceback (most recent call last):
  File "/data/django_serverauto/env/local/lib/python2.7/site-packages/django/core/handlers/base.py", line 101, in get_response
    resolver_match = resolver.resolve(request.path_info)
  File "/data/django_serverauto/env/local/lib/python2.7/site-packages/django/core/urlresolvers.py", line 320, in resolve
    sub_match = pattern.resolve(new_path)
  File "/data/django_serverauto/env/local/lib/python2.7/site-packages/django/core/urlresolvers.py", line 320, in resolve
    sub_match = pattern.resolve(new_path)
  File "/data/django_serverauto/env/local/lib/python2.7/site-packages/django/core/urlresolvers.py", line 222, in resolve
    return ResolverMatch(self.callback, args, kwargs, self.name)
  File "/data/django_serverauto/env/local/lib/python2.7/site-packages/django/core/urlresolvers.py", line 229, in callback
    self._callback = get_callable(self._callback_str)
  File "/data/django_serverauto/env/local/lib/python2.7/site-packages/django/utils/functional.py", line 32, in wrapper
    result = func(*args)
  File "/data/django_serverauto/env/local/lib/python2.7/site-packages/django/core/urlresolvers.py", line 96, in get_callable
    mod = import_module(mod_name)
  File "/data/django_serverauto/env/local/lib/python2.7/site-packages/django/utils/importlib.py", line 40, in import_module
    __import__(name)
  File "/data/django_serverauto/ServerAutoSys/app/views.py", line 16, in <module>
    from utils.MachineStatus import *
  File "/data/django_serverauto/ServerAutoSys/utils/MachineStatus.py", line 102
    groups = lambda: subprocess.Popen('netstat -tunlp | grep '\<:80\>, shell=True, stdout=subprocess.PIPE).stdout.read().strip()
                                                                                                                               ^
SyntaxError: unexpected character after line continuation character
[2015-03-03 23:02:15,971] [ERROR] base : Internal Server Error: /app/getMemInfo/
Traceback (most recent call last):
  File "/data/django_serverauto/env/local/lib/python2.7/site-packages/django/core/handlers/base.py", line 101, in get_response
    resolver_match = resolver.resolve(request.path_info)
  File "/data/django_serverauto/env/local/lib/python2.7/site-packages/django/core/urlresolvers.py", line 320, in resolve
    sub_match = pattern.resolve(new_path)
  File "/data/django_serverauto/env/local/lib/python2.7/site-packages/django/core/urlresolvers.py", line 320, in resolve
    sub_match = pattern.resolve(new_path)
  File "/data/django_serverauto/env/local/lib/python2.7/site-packages/django/core/urlresolvers.py", line 222, in resolve
    return ResolverMatch(self.callback, args, kwargs, self.name)
  File "/data/django_serverauto/env/local/lib/python2.7/site-packages/django/core/urlresolvers.py", line 229, in callback
    self._callback = get_callable(self._callback_str)
  File "/data/django_serverauto/env/local/lib/python2.7/site-packages/django/utils/functional.py", line 32, in wrapper
    result = func(*args)
  File "/data/django_serverauto/env/local/lib/python2.7/site-packages/django/core/urlresolvers.py", line 96, in get_callable
    mod = import_module(mod_name)
  File "/data/django_serverauto/env/local/lib/python2.7/site-packages/django/utils/importlib.py", line 40, in import_module
    __import__(name)
  File "/data/django_serverauto/ServerAutoSys/app/views.py", line 16, in <module>
    from utils.MachineStatus import *
  File "/data/django_serverauto/ServerAutoSys/utils/MachineStatus.py", line 102
    groups = lambda: subprocess.Popen('netstat -tunlp | grep '\<:80\>, shell=True, stdout=subprocess.PIPE).stdout.read().strip()
                                                                                                                               ^
SyntaxError: unexpected character after line continuation character
[2015-03-03 23:02:16,883] [ERROR] base : Internal Server Error: /app/getLoadAvg/
Traceback (most recent call last):
  File "/data/django_serverauto/env/local/lib/python2.7/site-packages/django/core/handlers/base.py", line 101, in get_response
    resolver_match = resolver.resolve(request.path_info)
  File "/data/django_serverauto/env/local/lib/python2.7/site-packages/django/core/urlresolvers.py", line 320, in resolve
    sub_match = pattern.resolve(new_path)
  File "/data/django_serverauto/env/local/lib/python2.7/site-packages/django/core/urlresolvers.py", line 320, in resolve
    sub_match = pattern.resolve(new_path)
  File "/data/django_serverauto/env/local/lib/python2.7/site-packages/django/core/urlresolvers.py", line 222, in resolve
    return ResolverMatch(self.callback, args, kwargs, self.name)
  File "/data/django_serverauto/env/local/lib/python2.7/site-packages/django/core/urlresolvers.py", line 229, in callback
    self._callback = get_callable(self._callback_str)
  File "/data/django_serverauto/env/local/lib/python2.7/site-packages/django/utils/functional.py", line 32, in wrapper
    result = func(*args)
  File "/data/django_serverauto/env/local/lib/python2.7/site-packages/django/core/urlresolvers.py", line 96, in get_callable
    mod = import_module(mod_name)
  File "/data/django_serverauto/env/local/lib/python2.7/site-packages/django/utils/importlib.py", line 40, in import_module
    __import__(name)
  File "/data/django_serverauto/ServerAutoSys/app/views.py", line 16, in <module>
    from utils.MachineStatus import *
  File "/data/django_serverauto/ServerAutoSys/utils/MachineStatus.py", line 102
    groups = lambda: subprocess.Popen('netstat -tunlp | grep '\<:80\>, shell=True, stdout=subprocess.PIPE).stdout.read().strip()
                                                                                                                               ^
SyntaxError: unexpected character after line continuation character
[2015-03-03 23:02:16,883] [ERROR] base : Internal Server Error: /app/getLoadAvg/
Traceback (most recent call last):
  File "/data/django_serverauto/env/local/lib/python2.7/site-packages/django/core/handlers/base.py", line 101, in get_response
    resolver_match = resolver.resolve(request.path_info)
  File "/data/django_serverauto/env/local/lib/python2.7/site-packages/django/core/urlresolvers.py", line 320, in resolve
    sub_match = pattern.resolve(new_path)
  File "/data/django_serverauto/env/local/lib/python2.7/site-packages/django/core/urlresolvers.py", line 320, in resolve
    sub_match = pattern.resolve(new_path)
  File "/data/django_serverauto/env/local/lib/python2.7/site-packages/django/core/urlresolvers.py", line 222, in resolve
    return ResolverMatch(self.callback, args, kwargs, self.name)
  File "/data/django_serverauto/env/local/lib/python2.7/site-packages/django/core/urlresolvers.py", line 229, in callback
    self._callback = get_callable(self._callback_str)
  File "/data/django_serverauto/env/local/lib/python2.7/site-packages/django/utils/functional.py", line 32, in wrapper
    result = func(*args)
  File "/data/django_serverauto/env/local/lib/python2.7/site-packages/django/core/urlresolvers.py", line 96, in get_callable
    mod = import_module(mod_name)
  File "/data/django_serverauto/env/local/lib/python2.7/site-packages/django/utils/importlib.py", line 40, in import_module
    __import__(name)
  File "/data/django_serverauto/ServerAutoSys/app/views.py", line 16, in <module>
    from utils.MachineStatus import *
  File "/data/django_serverauto/ServerAutoSys/utils/MachineStatus.py", line 102
    groups = lambda: subprocess.Popen('netstat -tunlp | grep '\<:80\>, shell=True, stdout=subprocess.PIPE).stdout.read().strip()
                                                                                                                               ^
SyntaxError: unexpected character after line continuation character
[2015-03-03 23:02:17,879] [ERROR] base : Internal Server Error: /app/getCpuInfo/
Traceback (most recent call last):
  File "/data/django_serverauto/env/local/lib/python2.7/site-packages/django/core/handlers/base.py", line 101, in get_response
    resolver_match = resolver.resolve(request.path_info)
  File "/data/django_serverauto/env/local/lib/python2.7/site-packages/django/core/urlresolvers.py", line 320, in resolve
    sub_match = pattern.resolve(new_path)
  File "/data/django_serverauto/env/local/lib/python2.7/site-packages/django/core/urlresolvers.py", line 320, in resolve
    sub_match = pattern.resolve(new_path)
  File "/data/django_serverauto/env/local/lib/python2.7/site-packages/django/core/urlresolvers.py", line 222, in resolve
    return ResolverMatch(self.callback, args, kwargs, self.name)
  File "/data/django_serverauto/env/local/lib/python2.7/site-packages/django/core/urlresolvers.py", line 229, in callback
    self._callback = get_callable(self._callback_str)
  File "/data/django_serverauto/env/local/lib/python2.7/site-packages/django/utils/functional.py", line 32, in wrapper
    result = func(*args)
  File "/data/django_serverauto/env/local/lib/python2.7/site-packages/django/core/urlresolvers.py", line 96, in get_callable
    mod = import_module(mod_name)
  File "/data/django_serverauto/env/local/lib/python2.7/site-packages/django/utils/importlib.py", line 40, in import_module
    __import__(name)
  File "/data/django_serverauto/ServerAutoSys/app/views.py", line 16, in <module>
    from utils.MachineStatus import *
  File "/data/django_serverauto/ServerAutoSys/utils/MachineStatus.py", line 102
    groups = lambda: subprocess.Popen('netstat -tunlp | grep '\<:80\>, shell=True, stdout=subprocess.PIPE).stdout.read().strip()
                                                                                                                               ^
SyntaxError: unexpected character after line continuation character
[2015-03-03 23:02:17,879] [ERROR] base : Internal Server Error: /app/getCpuInfo/
Traceback (most recent call last):
  File "/data/django_serverauto/env/local/lib/python2.7/site-packages/django/core/handlers/base.py", line 101, in get_response
    resolver_match = resolver.resolve(request.path_info)
  File "/data/django_serverauto/env/local/lib/python2.7/site-packages/django/core/urlresolvers.py", line 320, in resolve
    sub_match = pattern.resolve(new_path)
  File "/data/django_serverauto/env/local/lib/python2.7/site-packages/django/core/urlresolvers.py", line 320, in resolve
    sub_match = pattern.resolve(new_path)
  File "/data/django_serverauto/env/local/lib/python2.7/site-packages/django/core/urlresolvers.py", line 222, in resolve
    return ResolverMatch(self.callback, args, kwargs, self.name)
  File "/data/django_serverauto/env/local/lib/python2.7/site-packages/django/core/urlresolvers.py", line 229, in callback
    self._callback = get_callable(self._callback_str)
  File "/data/django_serverauto/env/local/lib/python2.7/site-packages/django/utils/functional.py", line 32, in wrapper
    result = func(*args)
  File "/data/django_serverauto/env/local/lib/python2.7/site-packages/django/core/urlresolvers.py", line 96, in get_callable
    mod = import_module(mod_name)
  File "/data/django_serverauto/env/local/lib/python2.7/site-packages/django/utils/importlib.py", line 40, in import_module
    __import__(name)
  File "/data/django_serverauto/ServerAutoSys/app/views.py", line 16, in <module>
    from utils.MachineStatus import *
  File "/data/django_serverauto/ServerAutoSys/utils/MachineStatus.py", line 102
    groups = lambda: subprocess.Popen('netstat -tunlp | grep '\<:80\>, shell=True, stdout=subprocess.PIPE).stdout.read().strip()
                                                                                                                               ^
SyntaxError: unexpected character after line continuation character
[2015-03-03 23:02:35,904] [ERROR] base : Internal Server Error: /app/getMemInfo/
Traceback (most recent call last):
  File "/data/django_serverauto/env/local/lib/python2.7/site-packages/django/core/handlers/base.py", line 101, in get_response
    resolver_match = resolver.resolve(request.path_info)
  File "/data/django_serverauto/env/local/lib/python2.7/site-packages/django/core/urlresolvers.py", line 320, in resolve
    sub_match = pattern.resolve(new_path)
  File "/data/django_serverauto/env/local/lib/python2.7/site-packages/django/core/urlresolvers.py", line 320, in resolve
    sub_match = pattern.resolve(new_path)
  File "/data/django_serverauto/env/local/lib/python2.7/site-packages/django/core/urlresolvers.py", line 222, in resolve
    return ResolverMatch(self.callback, args, kwargs, self.name)
  File "/data/django_serverauto/env/local/lib/python2.7/site-packages/django/core/urlresolvers.py", line 229, in callback
    self._callback = get_callable(self._callback_str)
  File "/data/django_serverauto/env/local/lib/python2.7/site-packages/django/utils/functional.py", line 32, in wrapper
    result = func(*args)
  File "/data/django_serverauto/env/local/lib/python2.7/site-packages/django/core/urlresolvers.py", line 96, in get_callable
    mod = import_module(mod_name)
  File "/data/django_serverauto/env/local/lib/python2.7/site-packages/django/utils/importlib.py", line 40, in import_module
    __import__(name)
  File "/data/django_serverauto/ServerAutoSys/app/views.py", line 16, in <module>
    from utils.MachineStatus import *
  File "/data/django_serverauto/ServerAutoSys/utils/MachineStatus.py", line 102
    groups = lambda: subprocess.Popen('netstat -tunlp | grep -c '\<:80\>, shell=True, stdout=subprocess.PIPE).stdout.read().strip()
                                                                                                                                  ^
SyntaxError: unexpected character after line continuation character
[2015-03-03 23:02:35,904] [ERROR] base : Internal Server Error: /app/getMemInfo/
Traceback (most recent call last):
  File "/data/django_serverauto/env/local/lib/python2.7/site-packages/django/core/handlers/base.py", line 101, in get_response
    resolver_match = resolver.resolve(request.path_info)
  File "/data/django_serverauto/env/local/lib/python2.7/site-packages/django/core/urlresolvers.py", line 320, in resolve
    sub_match = pattern.resolve(new_path)
  File "/data/django_serverauto/env/local/lib/python2.7/site-packages/django/core/urlresolvers.py", line 320, in resolve
    sub_match = pattern.resolve(new_path)
  File "/data/django_serverauto/env/local/lib/python2.7/site-packages/django/core/urlresolvers.py", line 222, in resolve
    return ResolverMatch(self.callback, args, kwargs, self.name)
  File "/data/django_serverauto/env/local/lib/python2.7/site-packages/django/core/urlresolvers.py", line 229, in callback
    self._callback = get_callable(self._callback_str)
  File "/data/django_serverauto/env/local/lib/python2.7/site-packages/django/utils/functional.py", line 32, in wrapper
    result = func(*args)
  File "/data/django_serverauto/env/local/lib/python2.7/site-packages/django/core/urlresolvers.py", line 96, in get_callable
    mod = import_module(mod_name)
  File "/data/django_serverauto/env/local/lib/python2.7/site-packages/django/utils/importlib.py", line 40, in import_module
    __import__(name)
  File "/data/django_serverauto/ServerAutoSys/app/views.py", line 16, in <module>
    from utils.MachineStatus import *
  File "/data/django_serverauto/ServerAutoSys/utils/MachineStatus.py", line 102
    groups = lambda: subprocess.Popen('netstat -tunlp | grep -c '\<:80\>, shell=True, stdout=subprocess.PIPE).stdout.read().strip()
                                                                                                                                  ^
SyntaxError: unexpected character after line continuation character
[2015-03-03 23:02:36,883] [ERROR] base : Internal Server Error: /app/getLoadAvg/
Traceback (most recent call last):
  File "/data/django_serverauto/env/local/lib/python2.7/site-packages/django/core/handlers/base.py", line 101, in get_response
    resolver_match = resolver.resolve(request.path_info)
  File "/data/django_serverauto/env/local/lib/python2.7/site-packages/django/core/urlresolvers.py", line 320, in resolve
    sub_match = pattern.resolve(new_path)
  File "/data/django_serverauto/env/local/lib/python2.7/site-packages/django/core/urlresolvers.py", line 320, in resolve
    sub_match = pattern.resolve(new_path)
  File "/data/django_serverauto/env/local/lib/python2.7/site-packages/django/core/urlresolvers.py", line 222, in resolve
    return ResolverMatch(self.callback, args, kwargs, self.name)
  File "/data/django_serverauto/env/local/lib/python2.7/site-packages/django/core/urlresolvers.py", line 229, in callback
    self._callback = get_callable(self._callback_str)
  File "/data/django_serverauto/env/local/lib/python2.7/site-packages/django/utils/functional.py", line 32, in wrapper
    result = func(*args)
  File "/data/django_serverauto/env/local/lib/python2.7/site-packages/django/core/urlresolvers.py", line 96, in get_callable
    mod = import_module(mod_name)
  File "/data/django_serverauto/env/local/lib/python2.7/site-packages/django/utils/importlib.py", line 40, in import_module
    __import__(name)
  File "/data/django_serverauto/ServerAutoSys/app/views.py", line 16, in <module>
    from utils.MachineStatus import *
  File "/data/django_serverauto/ServerAutoSys/utils/MachineStatus.py", line 102
    groups = lambda: subprocess.Popen('netstat -tunlp | grep -c '\<:80\>, shell=True, stdout=subprocess.PIPE).stdout.read().strip()
                                                                                                                                  ^
SyntaxError: unexpected character after line continuation character
[2015-03-03 23:02:36,883] [ERROR] base : Internal Server Error: /app/getLoadAvg/
Traceback (most recent call last):
  File "/data/django_serverauto/env/local/lib/python2.7/site-packages/django/core/handlers/base.py", line 101, in get_response
    resolver_match = resolver.resolve(request.path_info)
  File "/data/django_serverauto/env/local/lib/python2.7/site-packages/django/core/urlresolvers.py", line 320, in resolve
    sub_match = pattern.resolve(new_path)
  File "/data/django_serverauto/env/local/lib/python2.7/site-packages/django/core/urlresolvers.py", line 320, in resolve
    sub_match = pattern.resolve(new_path)
  File "/data/django_serverauto/env/local/lib/python2.7/site-packages/django/core/urlresolvers.py", line 222, in resolve
    return ResolverMatch(self.callback, args, kwargs, self.name)
  File "/data/django_serverauto/env/local/lib/python2.7/site-packages/django/core/urlresolvers.py", line 229, in callback
    self._callback = get_callable(self._callback_str)
  File "/data/django_serverauto/env/local/lib/python2.7/site-packages/django/utils/functional.py", line 32, in wrapper
    result = func(*args)
  File "/data/django_serverauto/env/local/lib/python2.7/site-packages/django/core/urlresolvers.py", line 96, in get_callable
    mod = import_module(mod_name)
  File "/data/django_serverauto/env/local/lib/python2.7/site-packages/django/utils/importlib.py", line 40, in import_module
    __import__(name)
  File "/data/django_serverauto/ServerAutoSys/app/views.py", line 16, in <module>
    from utils.MachineStatus import *
  File "/data/django_serverauto/ServerAutoSys/utils/MachineStatus.py", line 102
    groups = lambda: subprocess.Popen('netstat -tunlp | grep -c '\<:80\>, shell=True, stdout=subprocess.PIPE).stdout.read().strip()
                                                                                                                                  ^
SyntaxError: unexpected character after line continuation character
[2015-03-03 23:02:37,879] [ERROR] base : Internal Server Error: /app/getCpuInfo/
Traceback (most recent call last):
  File "/data/django_serverauto/env/local/lib/python2.7/site-packages/django/core/handlers/base.py", line 101, in get_response
    resolver_match = resolver.resolve(request.path_info)
  File "/data/django_serverauto/env/local/lib/python2.7/site-packages/django/core/urlresolvers.py", line 320, in resolve
    sub_match = pattern.resolve(new_path)
  File "/data/django_serverauto/env/local/lib/python2.7/site-packages/django/core/urlresolvers.py", line 320, in resolve
    sub_match = pattern.resolve(new_path)
  File "/data/django_serverauto/env/local/lib/python2.7/site-packages/django/core/urlresolvers.py", line 222, in resolve
    return ResolverMatch(self.callback, args, kwargs, self.name)
  File "/data/django_serverauto/env/local/lib/python2.7/site-packages/django/core/urlresolvers.py", line 229, in callback
    self._callback = get_callable(self._callback_str)
  File "/data/django_serverauto/env/local/lib/python2.7/site-packages/django/utils/functional.py", line 32, in wrapper
    result = func(*args)
  File "/data/django_serverauto/env/local/lib/python2.7/site-packages/django/core/urlresolvers.py", line 96, in get_callable
    mod = import_module(mod_name)
  File "/data/django_serverauto/env/local/lib/python2.7/site-packages/django/utils/importlib.py", line 40, in import_module
    __import__(name)
  File "/data/django_serverauto/ServerAutoSys/app/views.py", line 16, in <module>
    from utils.MachineStatus import *
  File "/data/django_serverauto/ServerAutoSys/utils/MachineStatus.py", line 102
    groups = lambda: subprocess.Popen('netstat -tunlp | grep -c '\<:80\>, shell=True, stdout=subprocess.PIPE).stdout.read().strip()
                                                                                                                                  ^
SyntaxError: unexpected character after line continuation character
[2015-03-03 23:02:37,879] [ERROR] base : Internal Server Error: /app/getCpuInfo/
Traceback (most recent call last):
  File "/data/django_serverauto/env/local/lib/python2.7/site-packages/django/core/handlers/base.py", line 101, in get_response
    resolver_match = resolver.resolve(request.path_info)
  File "/data/django_serverauto/env/local/lib/python2.7/site-packages/django/core/urlresolvers.py", line 320, in resolve
    sub_match = pattern.resolve(new_path)
  File "/data/django_serverauto/env/local/lib/python2.7/site-packages/django/core/urlresolvers.py", line 320, in resolve
    sub_match = pattern.resolve(new_path)
  File "/data/django_serverauto/env/local/lib/python2.7/site-packages/django/core/urlresolvers.py", line 222, in resolve
    return ResolverMatch(self.callback, args, kwargs, self.name)
  File "/data/django_serverauto/env/local/lib/python2.7/site-packages/django/core/urlresolvers.py", line 229, in callback
    self._callback = get_callable(self._callback_str)
  File "/data/django_serverauto/env/local/lib/python2.7/site-packages/django/utils/functional.py", line 32, in wrapper
    result = func(*args)
  File "/data/django_serverauto/env/local/lib/python2.7/site-packages/django/core/urlresolvers.py", line 96, in get_callable
    mod = import_module(mod_name)
  File "/data/django_serverauto/env/local/lib/python2.7/site-packages/django/utils/importlib.py", line 40, in import_module
    __import__(name)
  File "/data/django_serverauto/ServerAutoSys/app/views.py", line 16, in <module>
    from utils.MachineStatus import *
  File "/data/django_serverauto/ServerAutoSys/utils/MachineStatus.py", line 102
    groups = lambda: subprocess.Popen('netstat -tunlp | grep -c '\<:80\>, shell=True, stdout=subprocess.PIPE).stdout.read().strip()
                                                                                                                                  ^
SyntaxError: unexpected character after line continuation character
[2015-03-03 23:02:55,903] [ERROR] base : Internal Server Error: /app/getMemInfo/
Traceback (most recent call last):
  File "/data/django_serverauto/env/local/lib/python2.7/site-packages/django/core/handlers/base.py", line 101, in get_response
    resolver_match = resolver.resolve(request.path_info)
  File "/data/django_serverauto/env/local/lib/python2.7/site-packages/django/core/urlresolvers.py", line 320, in resolve
    sub_match = pattern.resolve(new_path)
  File "/data/django_serverauto/env/local/lib/python2.7/site-packages/django/core/urlresolvers.py", line 320, in resolve
    sub_match = pattern.resolve(new_path)
  File "/data/django_serverauto/env/local/lib/python2.7/site-packages/django/core/urlresolvers.py", line 222, in resolve
    return ResolverMatch(self.callback, args, kwargs, self.name)
  File "/data/django_serverauto/env/local/lib/python2.7/site-packages/django/core/urlresolvers.py", line 229, in callback
    self._callback = get_callable(self._callback_str)
  File "/data/django_serverauto/env/local/lib/python2.7/site-packages/django/utils/functional.py", line 32, in wrapper
    result = func(*args)
  File "/data/django_serverauto/env/local/lib/python2.7/site-packages/django/core/urlresolvers.py", line 96, in get_callable
    mod = import_module(mod_name)
  File "/data/django_serverauto/env/local/lib/python2.7/site-packages/django/utils/importlib.py", line 40, in import_module
    __import__(name)
  File "/data/django_serverauto/ServerAutoSys/app/views.py", line 16, in <module>
    from utils.MachineStatus import *
  File "/data/django_serverauto/ServerAutoSys/utils/MachineStatus.py", line 102
    groups = lambda: subprocess.Popen('netstat -tunlp | grep -c '\<:80\>, shell=True, stdout=subprocess.PIPE).stdout.read().strip()
                                                                                                                                  ^
SyntaxError: unexpected character after line continuation character
[2015-03-03 23:02:55,903] [ERROR] base : Internal Server Error: /app/getMemInfo/
Traceback (most recent call last):
  File "/data/django_serverauto/env/local/lib/python2.7/site-packages/django/core/handlers/base.py", line 101, in get_response
    resolver_match = resolver.resolve(request.path_info)
  File "/data/django_serverauto/env/local/lib/python2.7/site-packages/django/core/urlresolvers.py", line 320, in resolve
    sub_match = pattern.resolve(new_path)
  File "/data/django_serverauto/env/local/lib/python2.7/site-packages/django/core/urlresolvers.py", line 320, in resolve
    sub_match = pattern.resolve(new_path)
  File "/data/django_serverauto/env/local/lib/python2.7/site-packages/django/core/urlresolvers.py", line 222, in resolve
    return ResolverMatch(self.callback, args, kwargs, self.name)
  File "/data/django_serverauto/env/local/lib/python2.7/site-packages/django/core/urlresolvers.py", line 229, in callback
    self._callback = get_callable(self._callback_str)
  File "/data/django_serverauto/env/local/lib/python2.7/site-packages/django/utils/functional.py", line 32, in wrapper
    result = func(*args)
  File "/data/django_serverauto/env/local/lib/python2.7/site-packages/django/core/urlresolvers.py", line 96, in get_callable
    mod = import_module(mod_name)
  File "/data/django_serverauto/env/local/lib/python2.7/site-packages/django/utils/importlib.py", line 40, in import_module
    __import__(name)
  File "/data/django_serverauto/ServerAutoSys/app/views.py", line 16, in <module>
    from utils.MachineStatus import *
  File "/data/django_serverauto/ServerAutoSys/utils/MachineStatus.py", line 102
    groups = lambda: subprocess.Popen('netstat -tunlp | grep -c '\<:80\>, shell=True, stdout=subprocess.PIPE).stdout.read().strip()
                                                                                                                                  ^
SyntaxError: unexpected character after line continuation character
[2015-03-03 23:02:56,884] [ERROR] base : Internal Server Error: /app/getLoadAvg/
Traceback (most recent call last):
  File "/data/django_serverauto/env/local/lib/python2.7/site-packages/django/core/handlers/base.py", line 101, in get_response
    resolver_match = resolver.resolve(request.path_info)
  File "/data/django_serverauto/env/local/lib/python2.7/site-packages/django/core/urlresolvers.py", line 320, in resolve
    sub_match = pattern.resolve(new_path)
  File "/data/django_serverauto/env/local/lib/python2.7/site-packages/django/core/urlresolvers.py", line 320, in resolve
    sub_match = pattern.resolve(new_path)
  File "/data/django_serverauto/env/local/lib/python2.7/site-packages/django/core/urlresolvers.py", line 222, in resolve
    return ResolverMatch(self.callback, args, kwargs, self.name)
  File "/data/django_serverauto/env/local/lib/python2.7/site-packages/django/core/urlresolvers.py", line 229, in callback
    self._callback = get_callable(self._callback_str)
  File "/data/django_serverauto/env/local/lib/python2.7/site-packages/django/utils/functional.py", line 32, in wrapper
    result = func(*args)
  File "/data/django_serverauto/env/local/lib/python2.7/site-packages/django/core/urlresolvers.py", line 96, in get_callable
    mod = import_module(mod_name)
  File "/data/django_serverauto/env/local/lib/python2.7/site-packages/django/utils/importlib.py", line 40, in import_module
    __import__(name)
  File "/data/django_serverauto/ServerAutoSys/app/views.py", line 16, in <module>
    from utils.MachineStatus import *
  File "/data/django_serverauto/ServerAutoSys/utils/MachineStatus.py", line 102
    groups = lambda: subprocess.Popen('netstat -tunlp | grep -c '\<:80\>, shell=True, stdout=subprocess.PIPE).stdout.read().strip()
                                                                                                                                  ^
SyntaxError: unexpected character after line continuation character
[2015-03-03 23:02:56,884] [ERROR] base : Internal Server Error: /app/getLoadAvg/
Traceback (most recent call last):
  File "/data/django_serverauto/env/local/lib/python2.7/site-packages/django/core/handlers/base.py", line 101, in get_response
    resolver_match = resolver.resolve(request.path_info)
  File "/data/django_serverauto/env/local/lib/python2.7/site-packages/django/core/urlresolvers.py", line 320, in resolve
    sub_match = pattern.resolve(new_path)
  File "/data/django_serverauto/env/local/lib/python2.7/site-packages/django/core/urlresolvers.py", line 320, in resolve
    sub_match = pattern.resolve(new_path)
  File "/data/django_serverauto/env/local/lib/python2.7/site-packages/django/core/urlresolvers.py", line 222, in resolve
    return ResolverMatch(self.callback, args, kwargs, self.name)
  File "/data/django_serverauto/env/local/lib/python2.7/site-packages/django/core/urlresolvers.py", line 229, in callback
    self._callback = get_callable(self._callback_str)
  File "/data/django_serverauto/env/local/lib/python2.7/site-packages/django/utils/functional.py", line 32, in wrapper
    result = func(*args)
  File "/data/django_serverauto/env/local/lib/python2.7/site-packages/django/core/urlresolvers.py", line 96, in get_callable
    mod = import_module(mod_name)
  File "/data/django_serverauto/env/local/lib/python2.7/site-packages/django/utils/importlib.py", line 40, in import_module
    __import__(name)
  File "/data/django_serverauto/ServerAutoSys/app/views.py", line 16, in <module>
    from utils.MachineStatus import *
  File "/data/django_serverauto/ServerAutoSys/utils/MachineStatus.py", line 102
    groups = lambda: subprocess.Popen('netstat -tunlp | grep -c '\<:80\>, shell=True, stdout=subprocess.PIPE).stdout.read().strip()
                                                                                                                                  ^
SyntaxError: unexpected character after line continuation character
[2015-03-03 23:02:57,882] [ERROR] base : Internal Server Error: /app/getCpuInfo/
Traceback (most recent call last):
  File "/data/django_serverauto/env/local/lib/python2.7/site-packages/django/core/handlers/base.py", line 101, in get_response
    resolver_match = resolver.resolve(request.path_info)
  File "/data/django_serverauto/env/local/lib/python2.7/site-packages/django/core/urlresolvers.py", line 320, in resolve
    sub_match = pattern.resolve(new_path)
  File "/data/django_serverauto/env/local/lib/python2.7/site-packages/django/core/urlresolvers.py", line 320, in resolve
    sub_match = pattern.resolve(new_path)
  File "/data/django_serverauto/env/local/lib/python2.7/site-packages/django/core/urlresolvers.py", line 222, in resolve
    return ResolverMatch(self.callback, args, kwargs, self.name)
  File "/data/django_serverauto/env/local/lib/python2.7/site-packages/django/core/urlresolvers.py", line 229, in callback
    self._callback = get_callable(self._callback_str)
  File "/data/django_serverauto/env/local/lib/python2.7/site-packages/django/utils/functional.py", line 32, in wrapper
    result = func(*args)
  File "/data/django_serverauto/env/local/lib/python2.7/site-packages/django/core/urlresolvers.py", line 96, in get_callable
    mod = import_module(mod_name)
  File "/data/django_serverauto/env/local/lib/python2.7/site-packages/django/utils/importlib.py", line 40, in import_module
    __import__(name)
  File "/data/django_serverauto/ServerAutoSys/app/views.py", line 16, in <module>
    from utils.MachineStatus import *
  File "/data/django_serverauto/ServerAutoSys/utils/MachineStatus.py", line 102
    groups = lambda: subprocess.Popen('netstat -tunlp | grep -c '\<:80\>, shell=True, stdout=subprocess.PIPE).stdout.read().strip()
                                                                                                                                  ^
SyntaxError: unexpected character after line continuation character
[2015-03-03 23:02:57,882] [ERROR] base : Internal Server Error: /app/getCpuInfo/
Traceback (most recent call last):
  File "/data/django_serverauto/env/local/lib/python2.7/site-packages/django/core/handlers/base.py", line 101, in get_response
    resolver_match = resolver.resolve(request.path_info)
  File "/data/django_serverauto/env/local/lib/python2.7/site-packages/django/core/urlresolvers.py", line 320, in resolve
    sub_match = pattern.resolve(new_path)
  File "/data/django_serverauto/env/local/lib/python2.7/site-packages/django/core/urlresolvers.py", line 320, in resolve
    sub_match = pattern.resolve(new_path)
  File "/data/django_serverauto/env/local/lib/python2.7/site-packages/django/core/urlresolvers.py", line 222, in resolve
    return ResolverMatch(self.callback, args, kwargs, self.name)
  File "/data/django_serverauto/env/local/lib/python2.7/site-packages/django/core/urlresolvers.py", line 229, in callback
    self._callback = get_callable(self._callback_str)
  File "/data/django_serverauto/env/local/lib/python2.7/site-packages/django/utils/functional.py", line 32, in wrapper
    result = func(*args)
  File "/data/django_serverauto/env/local/lib/python2.7/site-packages/django/core/urlresolvers.py", line 96, in get_callable
    mod = import_module(mod_name)
  File "/data/django_serverauto/env/local/lib/python2.7/site-packages/django/utils/importlib.py", line 40, in import_module
    __import__(name)
  File "/data/django_serverauto/ServerAutoSys/app/views.py", line 16, in <module>
    from utils.MachineStatus import *
  File "/data/django_serverauto/ServerAutoSys/utils/MachineStatus.py", line 102
    groups = lambda: subprocess.Popen('netstat -tunlp | grep -c '\<:80\>, shell=True, stdout=subprocess.PIPE).stdout.read().strip()
                                                                                                                                  ^
SyntaxError: unexpected character after line continuation character
[2015-03-03 23:03:15,908] [ERROR] base : Internal Server Error: /app/getMemInfo/
Traceback (most recent call last):
  File "/data/django_serverauto/env/local/lib/python2.7/site-packages/django/core/handlers/base.py", line 101, in get_response
    resolver_match = resolver.resolve(request.path_info)
  File "/data/django_serverauto/env/local/lib/python2.7/site-packages/django/core/urlresolvers.py", line 320, in resolve
    sub_match = pattern.resolve(new_path)
  File "/data/django_serverauto/env/local/lib/python2.7/site-packages/django/core/urlresolvers.py", line 320, in resolve
    sub_match = pattern.resolve(new_path)
  File "/data/django_serverauto/env/local/lib/python2.7/site-packages/django/core/urlresolvers.py", line 222, in resolve
    return ResolverMatch(self.callback, args, kwargs, self.name)
  File "/data/django_serverauto/env/local/lib/python2.7/site-packages/django/core/urlresolvers.py", line 229, in callback
    self._callback = get_callable(self._callback_str)
  File "/data/django_serverauto/env/local/lib/python2.7/site-packages/django/utils/functional.py", line 32, in wrapper
    result = func(*args)
  File "/data/django_serverauto/env/local/lib/python2.7/site-packages/django/core/urlresolvers.py", line 96, in get_callable
    mod = import_module(mod_name)
  File "/data/django_serverauto/env/local/lib/python2.7/site-packages/django/utils/importlib.py", line 40, in import_module
    __import__(name)
  File "/data/django_serverauto/ServerAutoSys/app/views.py", line 16, in <module>
    from utils.MachineStatus import *
  File "/data/django_serverauto/ServerAutoSys/utils/MachineStatus.py", line 102
    ports = lambda: subprocess.Popen('netstat -tunlp | grep -c '\<:80\>, shell=True, stdout=subprocess.PIPE).stdout.read().strip()
                                                                                                                                 ^
SyntaxError: unexpected character after line continuation character
[2015-03-03 23:03:15,908] [ERROR] base : Internal Server Error: /app/getMemInfo/
Traceback (most recent call last):
  File "/data/django_serverauto/env/local/lib/python2.7/site-packages/django/core/handlers/base.py", line 101, in get_response
    resolver_match = resolver.resolve(request.path_info)
  File "/data/django_serverauto/env/local/lib/python2.7/site-packages/django/core/urlresolvers.py", line 320, in resolve
    sub_match = pattern.resolve(new_path)
  File "/data/django_serverauto/env/local/lib/python2.7/site-packages/django/core/urlresolvers.py", line 320, in resolve
    sub_match = pattern.resolve(new_path)
  File "/data/django_serverauto/env/local/lib/python2.7/site-packages/django/core/urlresolvers.py", line 222, in resolve
    return ResolverMatch(self.callback, args, kwargs, self.name)
  File "/data/django_serverauto/env/local/lib/python2.7/site-packages/django/core/urlresolvers.py", line 229, in callback
    self._callback = get_callable(self._callback_str)
  File "/data/django_serverauto/env/local/lib/python2.7/site-packages/django/utils/functional.py", line 32, in wrapper
    result = func(*args)
  File "/data/django_serverauto/env/local/lib/python2.7/site-packages/django/core/urlresolvers.py", line 96, in get_callable
    mod = import_module(mod_name)
  File "/data/django_serverauto/env/local/lib/python2.7/site-packages/django/utils/importlib.py", line 40, in import_module
    __import__(name)
  File "/data/django_serverauto/ServerAutoSys/app/views.py", line 16, in <module>
    from utils.MachineStatus import *
  File "/data/django_serverauto/ServerAutoSys/utils/MachineStatus.py", line 102
    ports = lambda: subprocess.Popen('netstat -tunlp | grep -c '\<:80\>, shell=True, stdout=subprocess.PIPE).stdout.read().strip()
                                                                                                                                 ^
SyntaxError: unexpected character after line continuation character
[2015-03-03 23:03:16,884] [ERROR] base : Internal Server Error: /app/getLoadAvg/
Traceback (most recent call last):
  File "/data/django_serverauto/env/local/lib/python2.7/site-packages/django/core/handlers/base.py", line 101, in get_response
    resolver_match = resolver.resolve(request.path_info)
  File "/data/django_serverauto/env/local/lib/python2.7/site-packages/django/core/urlresolvers.py", line 320, in resolve
    sub_match = pattern.resolve(new_path)
  File "/data/django_serverauto/env/local/lib/python2.7/site-packages/django/core/urlresolvers.py", line 320, in resolve
    sub_match = pattern.resolve(new_path)
  File "/data/django_serverauto/env/local/lib/python2.7/site-packages/django/core/urlresolvers.py", line 222, in resolve
    return ResolverMatch(self.callback, args, kwargs, self.name)
  File "/data/django_serverauto/env/local/lib/python2.7/site-packages/django/core/urlresolvers.py", line 229, in callback
    self._callback = get_callable(self._callback_str)
  File "/data/django_serverauto/env/local/lib/python2.7/site-packages/django/utils/functional.py", line 32, in wrapper
    result = func(*args)
  File "/data/django_serverauto/env/local/lib/python2.7/site-packages/django/core/urlresolvers.py", line 96, in get_callable
    mod = import_module(mod_name)
  File "/data/django_serverauto/env/local/lib/python2.7/site-packages/django/utils/importlib.py", line 40, in import_module
    __import__(name)
  File "/data/django_serverauto/ServerAutoSys/app/views.py", line 16, in <module>
    from utils.MachineStatus import *
  File "/data/django_serverauto/ServerAutoSys/utils/MachineStatus.py", line 102
    ports = lambda: subprocess.Popen('netstat -tunlp | grep -c '\<:80\>, shell=True, stdout=subprocess.PIPE).stdout.read().strip()
                                                                                                                                 ^
SyntaxError: unexpected character after line continuation character
[2015-03-03 23:03:16,884] [ERROR] base : Internal Server Error: /app/getLoadAvg/
Traceback (most recent call last):
  File "/data/django_serverauto/env/local/lib/python2.7/site-packages/django/core/handlers/base.py", line 101, in get_response
    resolver_match = resolver.resolve(request.path_info)
  File "/data/django_serverauto/env/local/lib/python2.7/site-packages/django/core/urlresolvers.py", line 320, in resolve
    sub_match = pattern.resolve(new_path)
  File "/data/django_serverauto/env/local/lib/python2.7/site-packages/django/core/urlresolvers.py", line 320, in resolve
    sub_match = pattern.resolve(new_path)
  File "/data/django_serverauto/env/local/lib/python2.7/site-packages/django/core/urlresolvers.py", line 222, in resolve
    return ResolverMatch(self.callback, args, kwargs, self.name)
  File "/data/django_serverauto/env/local/lib/python2.7/site-packages/django/core/urlresolvers.py", line 229, in callback
    self._callback = get_callable(self._callback_str)
  File "/data/django_serverauto/env/local/lib/python2.7/site-packages/django/utils/functional.py", line 32, in wrapper
    result = func(*args)
  File "/data/django_serverauto/env/local/lib/python2.7/site-packages/django/core/urlresolvers.py", line 96, in get_callable
    mod = import_module(mod_name)
  File "/data/django_serverauto/env/local/lib/python2.7/site-packages/django/utils/importlib.py", line 40, in import_module
    __import__(name)
  File "/data/django_serverauto/ServerAutoSys/app/views.py", line 16, in <module>
    from utils.MachineStatus import *
  File "/data/django_serverauto/ServerAutoSys/utils/MachineStatus.py", line 102
    ports = lambda: subprocess.Popen('netstat -tunlp | grep -c '\<:80\>, shell=True, stdout=subprocess.PIPE).stdout.read().strip()
                                                                                                                                 ^
SyntaxError: unexpected character after line continuation character
[2015-03-03 23:03:17,886] [ERROR] base : Internal Server Error: /app/getCpuInfo/
Traceback (most recent call last):
  File "/data/django_serverauto/env/local/lib/python2.7/site-packages/django/core/handlers/base.py", line 101, in get_response
    resolver_match = resolver.resolve(request.path_info)
  File "/data/django_serverauto/env/local/lib/python2.7/site-packages/django/core/urlresolvers.py", line 320, in resolve
    sub_match = pattern.resolve(new_path)
  File "/data/django_serverauto/env/local/lib/python2.7/site-packages/django/core/urlresolvers.py", line 320, in resolve
    sub_match = pattern.resolve(new_path)
  File "/data/django_serverauto/env/local/lib/python2.7/site-packages/django/core/urlresolvers.py", line 222, in resolve
    return ResolverMatch(self.callback, args, kwargs, self.name)
  File "/data/django_serverauto/env/local/lib/python2.7/site-packages/django/core/urlresolvers.py", line 229, in callback
    self._callback = get_callable(self._callback_str)
  File "/data/django_serverauto/env/local/lib/python2.7/site-packages/django/utils/functional.py", line 32, in wrapper
    result = func(*args)
  File "/data/django_serverauto/env/local/lib/python2.7/site-packages/django/core/urlresolvers.py", line 96, in get_callable
    mod = import_module(mod_name)
  File "/data/django_serverauto/env/local/lib/python2.7/site-packages/django/utils/importlib.py", line 40, in import_module
    __import__(name)
  File "/data/django_serverauto/ServerAutoSys/app/views.py", line 16, in <module>
    from utils.MachineStatus import *
  File "/data/django_serverauto/ServerAutoSys/utils/MachineStatus.py", line 102
    ports = lambda: subprocess.Popen('netstat -tunlp | grep -c '\<:80\>, shell=True, stdout=subprocess.PIPE).stdout.read().strip()
                                                                                                                                 ^
SyntaxError: unexpected character after line continuation character
[2015-03-03 23:03:17,886] [ERROR] base : Internal Server Error: /app/getCpuInfo/
Traceback (most recent call last):
  File "/data/django_serverauto/env/local/lib/python2.7/site-packages/django/core/handlers/base.py", line 101, in get_response
    resolver_match = resolver.resolve(request.path_info)
  File "/data/django_serverauto/env/local/lib/python2.7/site-packages/django/core/urlresolvers.py", line 320, in resolve
    sub_match = pattern.resolve(new_path)
  File "/data/django_serverauto/env/local/lib/python2.7/site-packages/django/core/urlresolvers.py", line 320, in resolve
    sub_match = pattern.resolve(new_path)
  File "/data/django_serverauto/env/local/lib/python2.7/site-packages/django/core/urlresolvers.py", line 222, in resolve
    return ResolverMatch(self.callback, args, kwargs, self.name)
  File "/data/django_serverauto/env/local/lib/python2.7/site-packages/django/core/urlresolvers.py", line 229, in callback
    self._callback = get_callable(self._callback_str)
  File "/data/django_serverauto/env/local/lib/python2.7/site-packages/django/utils/functional.py", line 32, in wrapper
    result = func(*args)
  File "/data/django_serverauto/env/local/lib/python2.7/site-packages/django/core/urlresolvers.py", line 96, in get_callable
    mod = import_module(mod_name)
  File "/data/django_serverauto/env/local/lib/python2.7/site-packages/django/utils/importlib.py", line 40, in import_module
    __import__(name)
  File "/data/django_serverauto/ServerAutoSys/app/views.py", line 16, in <module>
    from utils.MachineStatus import *
  File "/data/django_serverauto/ServerAutoSys/utils/MachineStatus.py", line 102
    ports = lambda: subprocess.Popen('netstat -tunlp | grep -c '\<:80\>, shell=True, stdout=subprocess.PIPE).stdout.read().strip()
                                                                                                                                 ^
SyntaxError: unexpected character after line continuation character
[2015-03-03 23:03:35,899] [ERROR] base : Internal Server Error: /app/getMemInfo/
Traceback (most recent call last):
  File "/data/django_serverauto/env/local/lib/python2.7/site-packages/django/core/handlers/base.py", line 101, in get_response
    resolver_match = resolver.resolve(request.path_info)
  File "/data/django_serverauto/env/local/lib/python2.7/site-packages/django/core/urlresolvers.py", line 320, in resolve
    sub_match = pattern.resolve(new_path)
  File "/data/django_serverauto/env/local/lib/python2.7/site-packages/django/core/urlresolvers.py", line 320, in resolve
    sub_match = pattern.resolve(new_path)
  File "/data/django_serverauto/env/local/lib/python2.7/site-packages/django/core/urlresolvers.py", line 222, in resolve
    return ResolverMatch(self.callback, args, kwargs, self.name)
  File "/data/django_serverauto/env/local/lib/python2.7/site-packages/django/core/urlresolvers.py", line 229, in callback
    self._callback = get_callable(self._callback_str)
  File "/data/django_serverauto/env/local/lib/python2.7/site-packages/django/utils/functional.py", line 32, in wrapper
    result = func(*args)
  File "/data/django_serverauto/env/local/lib/python2.7/site-packages/django/core/urlresolvers.py", line 96, in get_callable
    mod = import_module(mod_name)
  File "/data/django_serverauto/env/local/lib/python2.7/site-packages/django/utils/importlib.py", line 40, in import_module
    __import__(name)
  File "/data/django_serverauto/ServerAutoSys/app/views.py", line 16, in <module>
    from utils.MachineStatus import *
  File "/data/django_serverauto/ServerAutoSys/utils/MachineStatus.py", line 102
    ports = lambda: subprocess.Popen('netstat -tunlp | grep -c '\<:80\>, shell=True, stdout=subprocess.PIPE).stdout.read().strip()
                                                                                                                                 ^
SyntaxError: unexpected character after line continuation character
[2015-03-03 23:03:35,899] [ERROR] base : Internal Server Error: /app/getMemInfo/
Traceback (most recent call last):
  File "/data/django_serverauto/env/local/lib/python2.7/site-packages/django/core/handlers/base.py", line 101, in get_response
    resolver_match = resolver.resolve(request.path_info)
  File "/data/django_serverauto/env/local/lib/python2.7/site-packages/django/core/urlresolvers.py", line 320, in resolve
    sub_match = pattern.resolve(new_path)
  File "/data/django_serverauto/env/local/lib/python2.7/site-packages/django/core/urlresolvers.py", line 320, in resolve
    sub_match = pattern.resolve(new_path)
  File "/data/django_serverauto/env/local/lib/python2.7/site-packages/django/core/urlresolvers.py", line 222, in resolve
    return ResolverMatch(self.callback, args, kwargs, self.name)
  File "/data/django_serverauto/env/local/lib/python2.7/site-packages/django/core/urlresolvers.py", line 229, in callback
    self._callback = get_callable(self._callback_str)
  File "/data/django_serverauto/env/local/lib/python2.7/site-packages/django/utils/functional.py", line 32, in wrapper
    result = func(*args)
  File "/data/django_serverauto/env/local/lib/python2.7/site-packages/django/core/urlresolvers.py", line 96, in get_callable
    mod = import_module(mod_name)
  File "/data/django_serverauto/env/local/lib/python2.7/site-packages/django/utils/importlib.py", line 40, in import_module
    __import__(name)
  File "/data/django_serverauto/ServerAutoSys/app/views.py", line 16, in <module>
    from utils.MachineStatus import *
  File "/data/django_serverauto/ServerAutoSys/utils/MachineStatus.py", line 102
    ports = lambda: subprocess.Popen('netstat -tunlp | grep -c '\<:80\>, shell=True, stdout=subprocess.PIPE).stdout.read().strip()
                                                                                                                                 ^
SyntaxError: unexpected character after line continuation character
[2015-03-03 23:03:36,883] [ERROR] base : Internal Server Error: /app/getLoadAvg/
Traceback (most recent call last):
  File "/data/django_serverauto/env/local/lib/python2.7/site-packages/django/core/handlers/base.py", line 101, in get_response
    resolver_match = resolver.resolve(request.path_info)
  File "/data/django_serverauto/env/local/lib/python2.7/site-packages/django/core/urlresolvers.py", line 320, in resolve
    sub_match = pattern.resolve(new_path)
  File "/data/django_serverauto/env/local/lib/python2.7/site-packages/django/core/urlresolvers.py", line 320, in resolve
    sub_match = pattern.resolve(new_path)
  File "/data/django_serverauto/env/local/lib/python2.7/site-packages/django/core/urlresolvers.py", line 222, in resolve
    return ResolverMatch(self.callback, args, kwargs, self.name)
  File "/data/django_serverauto/env/local/lib/python2.7/site-packages/django/core/urlresolvers.py", line 229, in callback
    self._callback = get_callable(self._callback_str)
  File "/data/django_serverauto/env/local/lib/python2.7/site-packages/django/utils/functional.py", line 32, in wrapper
    result = func(*args)
  File "/data/django_serverauto/env/local/lib/python2.7/site-packages/django/core/urlresolvers.py", line 96, in get_callable
    mod = import_module(mod_name)
  File "/data/django_serverauto/env/local/lib/python2.7/site-packages/django/utils/importlib.py", line 40, in import_module
    __import__(name)
  File "/data/django_serverauto/ServerAutoSys/app/views.py", line 16, in <module>
    from utils.MachineStatus import *
  File "/data/django_serverauto/ServerAutoSys/utils/MachineStatus.py", line 102
    ports = lambda: subprocess.Popen('netstat -tunlp | grep -c '\<:80\>, shell=True, stdout=subprocess.PIPE).stdout.read().strip()
                                                                                                                                 ^
SyntaxError: unexpected character after line continuation character
[2015-03-03 23:03:36,883] [ERROR] base : Internal Server Error: /app/getLoadAvg/
Traceback (most recent call last):
  File "/data/django_serverauto/env/local/lib/python2.7/site-packages/django/core/handlers/base.py", line 101, in get_response
    resolver_match = resolver.resolve(request.path_info)
  File "/data/django_serverauto/env/local/lib/python2.7/site-packages/django/core/urlresolvers.py", line 320, in resolve
    sub_match = pattern.resolve(new_path)
  File "/data/django_serverauto/env/local/lib/python2.7/site-packages/django/core/urlresolvers.py", line 320, in resolve
    sub_match = pattern.resolve(new_path)
  File "/data/django_serverauto/env/local/lib/python2.7/site-packages/django/core/urlresolvers.py", line 222, in resolve
    return ResolverMatch(self.callback, args, kwargs, self.name)
  File "/data/django_serverauto/env/local/lib/python2.7/site-packages/django/core/urlresolvers.py", line 229, in callback
    self._callback = get_callable(self._callback_str)
  File "/data/django_serverauto/env/local/lib/python2.7/site-packages/django/utils/functional.py", line 32, in wrapper
    result = func(*args)
  File "/data/django_serverauto/env/local/lib/python2.7/site-packages/django/core/urlresolvers.py", line 96, in get_callable
    mod = import_module(mod_name)
  File "/data/django_serverauto/env/local/lib/python2.7/site-packages/django/utils/importlib.py", line 40, in import_module
    __import__(name)
  File "/data/django_serverauto/ServerAutoSys/app/views.py", line 16, in <module>
    from utils.MachineStatus import *
  File "/data/django_serverauto/ServerAutoSys/utils/MachineStatus.py", line 102
    ports = lambda: subprocess.Popen('netstat -tunlp | grep -c '\<:80\>, shell=True, stdout=subprocess.PIPE).stdout.read().strip()
                                                                                                                                 ^
SyntaxError: unexpected character after line continuation character
[2015-03-03 23:03:37,884] [ERROR] base : Internal Server Error: /app/getCpuInfo/
Traceback (most recent call last):
  File "/data/django_serverauto/env/local/lib/python2.7/site-packages/django/core/handlers/base.py", line 101, in get_response
    resolver_match = resolver.resolve(request.path_info)
  File "/data/django_serverauto/env/local/lib/python2.7/site-packages/django/core/urlresolvers.py", line 320, in resolve
    sub_match = pattern.resolve(new_path)
  File "/data/django_serverauto/env/local/lib/python2.7/site-packages/django/core/urlresolvers.py", line 320, in resolve
    sub_match = pattern.resolve(new_path)
  File "/data/django_serverauto/env/local/lib/python2.7/site-packages/django/core/urlresolvers.py", line 222, in resolve
    return ResolverMatch(self.callback, args, kwargs, self.name)
  File "/data/django_serverauto/env/local/lib/python2.7/site-packages/django/core/urlresolvers.py", line 229, in callback
    self._callback = get_callable(self._callback_str)
  File "/data/django_serverauto/env/local/lib/python2.7/site-packages/django/utils/functional.py", line 32, in wrapper
    result = func(*args)
  File "/data/django_serverauto/env/local/lib/python2.7/site-packages/django/core/urlresolvers.py", line 96, in get_callable
    mod = import_module(mod_name)
  File "/data/django_serverauto/env/local/lib/python2.7/site-packages/django/utils/importlib.py", line 40, in import_module
    __import__(name)
  File "/data/django_serverauto/ServerAutoSys/app/views.py", line 16, in <module>
    from utils.MachineStatus import *
  File "/data/django_serverauto/ServerAutoSys/utils/MachineStatus.py", line 102
    ports = lambda: subprocess.Popen('netstat -tunlp | grep -c '\<:80\>, shell=True, stdout=subprocess.PIPE).stdout.read().strip()
                                                                                                                                 ^
SyntaxError: unexpected character after line continuation character
[2015-03-03 23:03:37,884] [ERROR] base : Internal Server Error: /app/getCpuInfo/
Traceback (most recent call last):
  File "/data/django_serverauto/env/local/lib/python2.7/site-packages/django/core/handlers/base.py", line 101, in get_response
    resolver_match = resolver.resolve(request.path_info)
  File "/data/django_serverauto/env/local/lib/python2.7/site-packages/django/core/urlresolvers.py", line 320, in resolve
    sub_match = pattern.resolve(new_path)
  File "/data/django_serverauto/env/local/lib/python2.7/site-packages/django/core/urlresolvers.py", line 320, in resolve
    sub_match = pattern.resolve(new_path)
  File "/data/django_serverauto/env/local/lib/python2.7/site-packages/django/core/urlresolvers.py", line 222, in resolve
    return ResolverMatch(self.callback, args, kwargs, self.name)
  File "/data/django_serverauto/env/local/lib/python2.7/site-packages/django/core/urlresolvers.py", line 229, in callback
    self._callback = get_callable(self._callback_str)
  File "/data/django_serverauto/env/local/lib/python2.7/site-packages/django/utils/functional.py", line 32, in wrapper
    result = func(*args)
  File "/data/django_serverauto/env/local/lib/python2.7/site-packages/django/core/urlresolvers.py", line 96, in get_callable
    mod = import_module(mod_name)
  File "/data/django_serverauto/env/local/lib/python2.7/site-packages/django/utils/importlib.py", line 40, in import_module
    __import__(name)
  File "/data/django_serverauto/ServerAutoSys/app/views.py", line 16, in <module>
    from utils.MachineStatus import *
  File "/data/django_serverauto/ServerAutoSys/utils/MachineStatus.py", line 102
    ports = lambda: subprocess.Popen('netstat -tunlp | grep -c '\<:80\>, shell=True, stdout=subprocess.PIPE).stdout.read().strip()
                                                                                                                                 ^
SyntaxError: unexpected character after line continuation character
[2015-03-03 23:20:15,348] [INFO] views : index
[2015-03-03 23:25:11,626] [INFO] views : index
[2015-03-03 23:26:58,029] [INFO] views : index
[2015-03-03 23:28:56,035] [INFO] views : index
[2015-03-03 23:29:10,609] [INFO] views : index
[2015-03-03 23:56:54,401] [INFO] views : index
[2015-03-04 10:18:44,516] [ERROR] base : Internal Server Error: /
Traceback (most recent call last):
  File "/data/django_serverauto/env/lib/python2.6/site-packages/django/core/handlers/base.py", line 114, in get_response
    response = wrapped_callback(request, *callback_args, **callback_kwargs)
  File "/data/django_serverauto/ServerAutoSys/app/views.py", line 38, in login
    user = auth.authenticate(username = username, password = password)
  File "/data/django_serverauto/env/lib/python2.6/site-packages/django/contrib/auth/__init__.py", line 49, in authenticate
    user = backend.authenticate(**credentials)
  File "/data/django_serverauto/env/lib/python2.6/site-packages/django/contrib/auth/backends.py", line 16, in authenticate
    user = UserModel._default_manager.get_by_natural_key(username)
  File "/data/django_serverauto/env/lib/python2.6/site-packages/django/contrib/auth/models.py", line 167, in get_by_natural_key
    return self.get(**{self.model.USERNAME_FIELD: username})
  File "/data/django_serverauto/env/lib/python2.6/site-packages/django/db/models/manager.py", line 151, in get
    return self.get_queryset().get(*args, **kwargs)
  File "/data/django_serverauto/env/lib/python2.6/site-packages/django/db/models/query.py", line 301, in get
    num = len(clone)
  File "/data/django_serverauto/env/lib/python2.6/site-packages/django/db/models/query.py", line 77, in __len__
    self._fetch_all()
  File "/data/django_serverauto/env/lib/python2.6/site-packages/django/db/models/query.py", line 854, in _fetch_all
    self._result_cache = list(self.iterator())
  File "/data/django_serverauto/env/lib/python2.6/site-packages/django/db/models/query.py", line 220, in iterator
    for row in compiler.results_iter():
  File "/data/django_serverauto/env/lib/python2.6/site-packages/django/db/models/sql/compiler.py", line 710, in results_iter
    for rows in self.execute_sql(MULTI):
  File "/data/django_serverauto/env/lib/python2.6/site-packages/django/db/models/sql/compiler.py", line 780, in execute_sql
    cursor = self.connection.cursor()
  File "/data/django_serverauto/env/lib/python2.6/site-packages/django/db/backends/__init__.py", line 157, in cursor
    cursor = self.make_debug_cursor(self._cursor())
  File "/data/django_serverauto/env/lib/python2.6/site-packages/django/db/backends/__init__.py", line 129, in _cursor
    self.ensure_connection()
  File "/data/django_serverauto/env/lib/python2.6/site-packages/django/db/backends/__init__.py", line 124, in ensure_connection
    self.connect()
  File "/data/django_serverauto/env/lib/python2.6/site-packages/django/db/utils.py", line 99, in __exit__
    six.reraise(dj_exc_type, dj_exc_value, traceback)
  File "/data/django_serverauto/env/lib/python2.6/site-packages/django/db/backends/__init__.py", line 124, in ensure_connection
    self.connect()
  File "/data/django_serverauto/env/lib/python2.6/site-packages/django/db/backends/__init__.py", line 112, in connect
    self.connection = self.get_new_connection(conn_params)
  File "/data/django_serverauto/env/lib/python2.6/site-packages/django/db/backends/mysql/base.py", line 435, in get_new_connection
    conn = Database.connect(**conn_params)
  File "/data/django_serverauto/env/lib/python2.6/site-packages/MySQLdb/__init__.py", line 81, in Connect
    return Connection(*args, **kwargs)
  File "/data/django_serverauto/env/lib/python2.6/site-packages/MySQLdb/connections.py", line 193, in __init__
    super(Connection, self).__init__(*args, **kwargs2)
OperationalError: (2003, "Can't connect to MySQL server on '127.0.0.1' (111)")
[2015-03-04 10:18:44,516] [ERROR] base : Internal Server Error: /
Traceback (most recent call last):
  File "/data/django_serverauto/env/lib/python2.6/site-packages/django/core/handlers/base.py", line 114, in get_response
    response = wrapped_callback(request, *callback_args, **callback_kwargs)
  File "/data/django_serverauto/ServerAutoSys/app/views.py", line 38, in login
    user = auth.authenticate(username = username, password = password)
  File "/data/django_serverauto/env/lib/python2.6/site-packages/django/contrib/auth/__init__.py", line 49, in authenticate
    user = backend.authenticate(**credentials)
  File "/data/django_serverauto/env/lib/python2.6/site-packages/django/contrib/auth/backends.py", line 16, in authenticate
    user = UserModel._default_manager.get_by_natural_key(username)
  File "/data/django_serverauto/env/lib/python2.6/site-packages/django/contrib/auth/models.py", line 167, in get_by_natural_key
    return self.get(**{self.model.USERNAME_FIELD: username})
  File "/data/django_serverauto/env/lib/python2.6/site-packages/django/db/models/manager.py", line 151, in get
    return self.get_queryset().get(*args, **kwargs)
  File "/data/django_serverauto/env/lib/python2.6/site-packages/django/db/models/query.py", line 301, in get
    num = len(clone)
  File "/data/django_serverauto/env/lib/python2.6/site-packages/django/db/models/query.py", line 77, in __len__
    self._fetch_all()
  File "/data/django_serverauto/env/lib/python2.6/site-packages/django/db/models/query.py", line 854, in _fetch_all
    self._result_cache = list(self.iterator())
  File "/data/django_serverauto/env/lib/python2.6/site-packages/django/db/models/query.py", line 220, in iterator
    for row in compiler.results_iter():
  File "/data/django_serverauto/env/lib/python2.6/site-packages/django/db/models/sql/compiler.py", line 710, in results_iter
    for rows in self.execute_sql(MULTI):
  File "/data/django_serverauto/env/lib/python2.6/site-packages/django/db/models/sql/compiler.py", line 780, in execute_sql
    cursor = self.connection.cursor()
  File "/data/django_serverauto/env/lib/python2.6/site-packages/django/db/backends/__init__.py", line 157, in cursor
    cursor = self.make_debug_cursor(self._cursor())
  File "/data/django_serverauto/env/lib/python2.6/site-packages/django/db/backends/__init__.py", line 129, in _cursor
    self.ensure_connection()
  File "/data/django_serverauto/env/lib/python2.6/site-packages/django/db/backends/__init__.py", line 124, in ensure_connection
    self.connect()
  File "/data/django_serverauto/env/lib/python2.6/site-packages/django/db/utils.py", line 99, in __exit__
    six.reraise(dj_exc_type, dj_exc_value, traceback)
  File "/data/django_serverauto/env/lib/python2.6/site-packages/django/db/backends/__init__.py", line 124, in ensure_connection
    self.connect()
  File "/data/django_serverauto/env/lib/python2.6/site-packages/django/db/backends/__init__.py", line 112, in connect
    self.connection = self.get_new_connection(conn_params)
  File "/data/django_serverauto/env/lib/python2.6/site-packages/django/db/backends/mysql/base.py", line 435, in get_new_connection
    conn = Database.connect(**conn_params)
  File "/data/django_serverauto/env/lib/python2.6/site-packages/MySQLdb/__init__.py", line 81, in Connect
    return Connection(*args, **kwargs)
  File "/data/django_serverauto/env/lib/python2.6/site-packages/MySQLdb/connections.py", line 193, in __init__
    super(Connection, self).__init__(*args, **kwargs2)
OperationalError: (2003, "Can't connect to MySQL server on '127.0.0.1' (111)")
[2015-03-04 10:19:03,959] [INFO] views : index
[2015-03-04 10:19:19,458] [INFO] views : index
[2015-03-04 10:21:08,089] [ERROR] base : Internal Server Error: /app/getServerList/
Traceback (most recent call last):
  File "/data/django_serverauto/env/lib/python2.6/site-packages/django/core/handlers/base.py", line 114, in get_response
    response = wrapped_callback(request, *callback_args, **callback_kwargs)
  File "/data/django_serverauto/env/lib/python2.6/site-packages/django/contrib/auth/decorators.py", line 22, in _wrapped_view
    return view_func(request, *args, **kwargs)
  File "/data/django_serverauto/ServerAutoSys/app/views.py", line 150, in getServerList
    print server_list
  File "/data/django_serverauto/env/lib/python2.6/site-packages/django/db/models/query.py", line 71, in __repr__
    data = list(self[:REPR_OUTPUT_SIZE + 1])
  File "/data/django_serverauto/env/lib/python2.6/site-packages/django/db/models/query.py", line 96, in __iter__
    self._fetch_all()
  File "/data/django_serverauto/env/lib/python2.6/site-packages/django/db/models/query.py", line 854, in _fetch_all
    self._result_cache = list(self.iterator())
  File "/data/django_serverauto/env/lib/python2.6/site-packages/django/db/models/query.py", line 220, in iterator
    for row in compiler.results_iter():
  File "/data/django_serverauto/env/lib/python2.6/site-packages/django/db/models/sql/compiler.py", line 710, in results_iter
    for rows in self.execute_sql(MULTI):
  File "/data/django_serverauto/env/lib/python2.6/site-packages/django/db/models/sql/compiler.py", line 781, in execute_sql
    cursor.execute(sql, params)
  File "/data/django_serverauto/env/lib/python2.6/site-packages/django/db/backends/util.py", line 69, in execute
    return super(CursorDebugWrapper, self).execute(sql, params)
  File "/data/django_serverauto/env/lib/python2.6/site-packages/django/db/backends/util.py", line 53, in execute
    return self.cursor.execute(sql, params)
  File "/data/django_serverauto/env/lib/python2.6/site-packages/django/db/utils.py", line 99, in __exit__
    six.reraise(dj_exc_type, dj_exc_value, traceback)
  File "/data/django_serverauto/env/lib/python2.6/site-packages/django/db/backends/util.py", line 53, in execute
    return self.cursor.execute(sql, params)
  File "/data/django_serverauto/env/lib/python2.6/site-packages/django/db/backends/mysql/base.py", line 124, in execute
    return self.cursor.execute(query, args)
  File "/data/django_serverauto/env/lib/python2.6/site-packages/MySQLdb/cursors.py", line 205, in execute
    self.errorhandler(self, exc, value)
  File "/data/django_serverauto/env/lib/python2.6/site-packages/MySQLdb/connections.py", line 36, in defaulterrorhandler
    raise errorclass, errorvalue
OperationalError: (1054, "Unknown column 'server_list.server_snmp_on' in 'field list'")
[2015-03-04 10:21:08,089] [ERROR] base : Internal Server Error: /app/getServerList/
Traceback (most recent call last):
  File "/data/django_serverauto/env/lib/python2.6/site-packages/django/core/handlers/base.py", line 114, in get_response
    response = wrapped_callback(request, *callback_args, **callback_kwargs)
  File "/data/django_serverauto/env/lib/python2.6/site-packages/django/contrib/auth/decorators.py", line 22, in _wrapped_view
    return view_func(request, *args, **kwargs)
  File "/data/django_serverauto/ServerAutoSys/app/views.py", line 150, in getServerList
    print server_list
  File "/data/django_serverauto/env/lib/python2.6/site-packages/django/db/models/query.py", line 71, in __repr__
    data = list(self[:REPR_OUTPUT_SIZE + 1])
  File "/data/django_serverauto/env/lib/python2.6/site-packages/django/db/models/query.py", line 96, in __iter__
    self._fetch_all()
  File "/data/django_serverauto/env/lib/python2.6/site-packages/django/db/models/query.py", line 854, in _fetch_all
    self._result_cache = list(self.iterator())
  File "/data/django_serverauto/env/lib/python2.6/site-packages/django/db/models/query.py", line 220, in iterator
    for row in compiler.results_iter():
  File "/data/django_serverauto/env/lib/python2.6/site-packages/django/db/models/sql/compiler.py", line 710, in results_iter
    for rows in self.execute_sql(MULTI):
  File "/data/django_serverauto/env/lib/python2.6/site-packages/django/db/models/sql/compiler.py", line 781, in execute_sql
    cursor.execute(sql, params)
  File "/data/django_serverauto/env/lib/python2.6/site-packages/django/db/backends/util.py", line 69, in execute
    return super(CursorDebugWrapper, self).execute(sql, params)
  File "/data/django_serverauto/env/lib/python2.6/site-packages/django/db/backends/util.py", line 53, in execute
    return self.cursor.execute(sql, params)
  File "/data/django_serverauto/env/lib/python2.6/site-packages/django/db/utils.py", line 99, in __exit__
    six.reraise(dj_exc_type, dj_exc_value, traceback)
  File "/data/django_serverauto/env/lib/python2.6/site-packages/django/db/backends/util.py", line 53, in execute
    return self.cursor.execute(sql, params)
  File "/data/django_serverauto/env/lib/python2.6/site-packages/django/db/backends/mysql/base.py", line 124, in execute
    return self.cursor.execute(query, args)
  File "/data/django_serverauto/env/lib/python2.6/site-packages/MySQLdb/cursors.py", line 205, in execute
    self.errorhandler(self, exc, value)
  File "/data/django_serverauto/env/lib/python2.6/site-packages/MySQLdb/connections.py", line 36, in defaulterrorhandler
    raise errorclass, errorvalue
OperationalError: (1054, "Unknown column 'server_list.server_snmp_on' in 'field list'")
[2015-03-04 10:22:23,737] [INFO] views : index
[2015-03-04 10:23:02,234] [INFO] views : index
[2015-03-04 10:37:35,588] [INFO] views : index
[2015-03-04 11:05:07,529] [INFO] views : index
[2015-03-04 11:47:16,242] [INFO] views : index
[2015-03-04 11:49:22,018] [INFO] views : index
[2015-03-04 11:52:19,512] [INFO] views : index
